Apr 08 00:28:34.73
GET
500
ahmedhellly.vercel.app
/student/video/2
ith_frames_removed File "/var/task/main.py", line 87, in <module> db.create_all() File "/var/task/flask_sqlalchemy/extension.py", line 900, in create_all self._call_for_binds(bind_key, "create_all") File "/var/task/flask_sqlalchemy/extension.py", line 881, in _call_for_binds getattr(metadata, op_name)(bind=engine) File "/var/task/sqlalchemy/sql/schema.py", line 5925, in create_all bind._run_ddl_visitor( File "/var/task/sqlalchemy/engine/base.py", line 3248, in _run_ddl_visitor with self.begin() as conn: ^^^^^^^^^^^^ File "/var/lang/lib/python3.12/contextlib.py", line 137, in __enter__ return next(self.gen) ^^^^^^^^^^^^^^ File "/var/task/sqlalchemy/engine/base.py", line 3238, in begin with self.connect() as conn: ^^^^^^^^^^^^^^ File "/var/task/sqlalchemy/engine/base.py", line 3274, in connect return self._connection_cls(self) ^^^^^^^^^^^^^^^^^^^^^^^^^^ File "/var/task/sqlalchemy/engine/base.py", line 148, in __init__ Connection._handle_dbapi_exception_noconnection( File "/var/task/sqlalchemy/engine/base.py", line 2439, in _handle_dbapi_exception_noconnection raise sqlalchemy_exception.with_traceback(exc_info[2]) from e File "/var/task/sqlalchemy/engine/base.py", line 146, in __init__ self._dbapi_connection = engine.raw_connection() ^^^^^^^^^^^^^^^^^^^^^^^ File "/var/task/sqlalchemy/engine/base.py", line 3298, in raw_connection return self.pool.connect() ^^^^^^^^^^^^^^^^^^^ File "/var/task/sqlalchemy/pool/base.py", line 449, in connect return _ConnectionFairy._checkout(self) ^^^^^^^^^^^^^^^^^^^^^^^^^^^^^^^^ File "/var/task/sqlalchemy/pool/base.py", line 1264, in _checkout fairy = _ConnectionRecord.checkout(pool) ^^^^^^^^^^^^^^^^^^^^^^^^^^^^^^^^ File "/var/task/sqlalchemy/pool/base.py", line 713, in checkout rec = pool._do_get() ^^^^^^^^^^^^^^ File "/var/task/sqlalchemy/pool/impl.py", line 179, in _do_get with util.safe_reraise(): ^^^^^^^^^^^^^^^^^^^ File "/var/task/sqlalchemy/util/langhelpers.py", line 146, in __exit__ raise exc_value.with_traceback(exc_tb) File "/var/task/sqlalchemy/pool/impl.py", line 177, in _do_get return self._create_connection() ^^^^^^^^^^^^^^^^^^^^^^^^^ File "/var/task/sqlalchemy/pool/base.py", line 390, in _create_connection return _ConnectionRecord(self) ^^^^^^^^^^^^^^^^^^^^^^^ File "/var/task/sqlalchemy/pool/base.py", line 675, in __init__ self.__connect() File "/var/task/sqlalchemy/pool/base.py", line 901, in __connect with util.safe_reraise(): ^^^^^^^^^^^^^^^^^^^ File "/var/task/sqlalchemy/util/langhelpers.py", line 146, in __exit__ raise exc_value.with_traceback(exc_tb) File "/var/task/sqlalchemy/pool/base.py", line 897, in __connect self.dbapi_connection = connection = pool._invoke_creator(self) ^^^^^^^^^^^^^^^^^^^^^^^^^^ File "/var/task/sqlalchemy/engine/create.py", line 646, in connect return dialect.connect(*cargs, **cparams) ^^^^^^^^^^^^^^^^^^^^^^^^^^^^^^^^^^ File "/var/task/sqlalchemy/engine/default.py", line 625, in connect return self.loaded_dbapi.connect(*cargs, **cparams) # type: ignore[no-any-return] # NOQA: E501 ^^^^^^^^^^^^^^^^^^^^^^^^^^^^^^^^^^^^^^^^^^^^ File "/var/task/psycopg2/__init__.py", line 122, in connect conn = _connect(dsn, connection_factory=connection_factory, **kwasync) ^^^^^^^^^^^^^^^^^^^^^^^^^^^^^^^^^^^^^^^^^^^^^^^^^^^^^^^^^^^^^^^ sqlalchemy.exc.OperationalError: (psycopg2.OperationalError) connection to server at "db.pjomptqavgnixbcoomvy.supabase.co" (2a05:d014:1c06:5f0f:d8b7:40ee:d73f:2bb2), port 5432 failed: Cannot assign requested address Is the server running on that host and accepting TCP/IP connections? (Background on this error at: https://sqlalche.me/e/20/e3q8) Python process exited with exit status: 1. The logs above can help with debugging the issue.
Apr 08 00:28:33.48
GET
500
ahmedhellly.vercel.app
/student/video/2
ith_frames_removed File "/var/task/main.py", line 87, in <module> db.create_all() File "/var/task/flask_sqlalchemy/extension.py", line 900, in create_all self._call_for_binds(bind_key, "create_all") File "/var/task/flask_sqlalchemy/extension.py", line 881, in _call_for_binds getattr(metadata, op_name)(bind=engine) File "/var/task/sqlalchemy/sql/schema.py", line 5925, in create_all bind._run_ddl_visitor( File "/var/task/sqlalchemy/engine/base.py", line 3248, in _run_ddl_visitor with self.begin() as conn: ^^^^^^^^^^^^ File "/var/lang/lib/python3.12/contextlib.py", line 137, in __enter__ return next(self.gen) ^^^^^^^^^^^^^^ File "/var/task/sqlalchemy/engine/base.py", line 3238, in begin with self.connect() as conn: ^^^^^^^^^^^^^^ File "/var/task/sqlalchemy/engine/base.py", line 3274, in connect return self._connection_cls(self) ^^^^^^^^^^^^^^^^^^^^^^^^^^ File "/var/task/sqlalchemy/engine/base.py", line 148, in __init__ Connection._handle_dbapi_exception_noconnection( File "/var/task/sqlalchemy/engine/base.py", line 2439, in _handle_dbapi_exception_noconnection raise sqlalchemy_exception.with_traceback(exc_info[2]) from e File "/var/task/sqlalchemy/engine/base.py", line 146, in __init__ self._dbapi_connection = engine.raw_connection() ^^^^^^^^^^^^^^^^^^^^^^^ File "/var/task/sqlalchemy/engine/base.py", line 3298, in raw_connection return self.pool.connect() ^^^^^^^^^^^^^^^^^^^ File "/var/task/sqlalchemy/pool/base.py", line 449, in connect return _ConnectionFairy._checkout(self) ^^^^^^^^^^^^^^^^^^^^^^^^^^^^^^^^ File "/var/task/sqlalchemy/pool/base.py", line 1264, in _checkout fairy = _ConnectionRecord.checkout(pool) ^^^^^^^^^^^^^^^^^^^^^^^^^^^^^^^^ File "/var/task/sqlalchemy/pool/base.py", line 713, in checkout rec = pool._do_get() ^^^^^^^^^^^^^^ File "/var/task/sqlalchemy/pool/impl.py", line 179, in _do_get with util.safe_reraise(): ^^^^^^^^^^^^^^^^^^^ File "/var/task/sqlalchemy/util/langhelpers.py", line 146, in __exit__ raise exc_value.with_traceback(exc_tb) File "/var/task/sqlalchemy/pool/impl.py", line 177, in _do_get return self._create_connection() ^^^^^^^^^^^^^^^^^^^^^^^^^ File "/var/task/sqlalchemy/pool/base.py", line 390, in _create_connection return _ConnectionRecord(self) ^^^^^^^^^^^^^^^^^^^^^^^ File "/var/task/sqlalchemy/pool/base.py", line 675, in __init__ self.__connect() File "/var/task/sqlalchemy/pool/base.py", line 901, in __connect with util.safe_reraise(): ^^^^^^^^^^^^^^^^^^^ File "/var/task/sqlalchemy/util/langhelpers.py", line 146, in __exit__ raise exc_value.with_traceback(exc_tb) File "/var/task/sqlalchemy/pool/base.py", line 897, in __connect self.dbapi_connection = connection = pool._invoke_creator(self) ^^^^^^^^^^^^^^^^^^^^^^^^^^ File "/var/task/sqlalchemy/engine/create.py", line 646, in connect return dialect.connect(*cargs, **cparams) ^^^^^^^^^^^^^^^^^^^^^^^^^^^^^^^^^^ File "/var/task/sqlalchemy/engine/default.py", line 625, in connect return self.loaded_dbapi.connect(*cargs, **cparams) # type: ignore[no-any-return] # NOQA: E501 ^^^^^^^^^^^^^^^^^^^^^^^^^^^^^^^^^^^^^^^^^^^^ File "/var/task/psycopg2/__init__.py", line 122, in connect conn = _connect(dsn, connection_factory=connection_factory, **kwasync) ^^^^^^^^^^^^^^^^^^^^^^^^^^^^^^^^^^^^^^^^^^^^^^^^^^^^^^^^^^^^^^^ sqlalchemy.exc.OperationalError: (psycopg2.OperationalError) connection to server at "db.pjomptqavgnixbcoomvy.supabase.co" (2a05:d014:1c06:5f0f:d8b7:40ee:d73f:2bb2), port 5432 failed: Cannot assign requested address Is the server running on that host and accepting TCP/IP connections? (Background on this error at: https://sqlalche.me/e/20/e3q8) Python process exited with exit status: 1. The logs above can help with debugging the issue.
Apr 08 00:28:32.17
GET
500
ahmedhellly.vercel.app
/student/video/2
ith_frames_removed File "/var/task/main.py", line 87, in <module> db.create_all() File "/var/task/flask_sqlalchemy/extension.py", line 900, in create_all self._call_for_binds(bind_key, "create_all") File "/var/task/flask_sqlalchemy/extension.py", line 881, in _call_for_binds getattr(metadata, op_name)(bind=engine) File "/var/task/sqlalchemy/sql/schema.py", line 5925, in create_all bind._run_ddl_visitor( File "/var/task/sqlalchemy/engine/base.py", line 3248, in _run_ddl_visitor with self.begin() as conn: ^^^^^^^^^^^^ File "/var/lang/lib/python3.12/contextlib.py", line 137, in __enter__ return next(self.gen) ^^^^^^^^^^^^^^ File "/var/task/sqlalchemy/engine/base.py", line 3238, in begin with self.connect() as conn: ^^^^^^^^^^^^^^ File "/var/task/sqlalchemy/engine/base.py", line 3274, in connect return self._connection_cls(self) ^^^^^^^^^^^^^^^^^^^^^^^^^^ File "/var/task/sqlalchemy/engine/base.py", line 148, in __init__ Connection._handle_dbapi_exception_noconnection( File "/var/task/sqlalchemy/engine/base.py", line 2439, in _handle_dbapi_exception_noconnection raise sqlalchemy_exception.with_traceback(exc_info[2]) from e File "/var/task/sqlalchemy/engine/base.py", line 146, in __init__ self._dbapi_connection = engine.raw_connection() ^^^^^^^^^^^^^^^^^^^^^^^ File "/var/task/sqlalchemy/engine/base.py", line 3298, in raw_connection return self.pool.connect() ^^^^^^^^^^^^^^^^^^^ File "/var/task/sqlalchemy/pool/base.py", line 449, in connect return _ConnectionFairy._checkout(self) ^^^^^^^^^^^^^^^^^^^^^^^^^^^^^^^^ File "/var/task/sqlalchemy/pool/base.py", line 1264, in _checkout fairy = _ConnectionRecord.checkout(pool) ^^^^^^^^^^^^^^^^^^^^^^^^^^^^^^^^ File "/var/task/sqlalchemy/pool/base.py", line 713, in checkout rec = pool._do_get() ^^^^^^^^^^^^^^ File "/var/task/sqlalchemy/pool/impl.py", line 179, in _do_get with util.safe_reraise(): ^^^^^^^^^^^^^^^^^^^ File "/var/task/sqlalchemy/util/langhelpers.py", line 146, in __exit__ raise exc_value.with_traceback(exc_tb) File "/var/task/sqlalchemy/pool/impl.py", line 177, in _do_get return self._create_connection() ^^^^^^^^^^^^^^^^^^^^^^^^^ File "/var/task/sqlalchemy/pool/base.py", line 390, in _create_connection return _ConnectionRecord(self) ^^^^^^^^^^^^^^^^^^^^^^^ File "/var/task/sqlalchemy/pool/base.py", line 675, in __init__ self.__connect() File "/var/task/sqlalchemy/pool/base.py", line 901, in __connect with util.safe_reraise(): ^^^^^^^^^^^^^^^^^^^ File "/var/task/sqlalchemy/util/langhelpers.py", line 146, in __exit__ raise exc_value.with_traceback(exc_tb) File "/var/task/sqlalchemy/pool/base.py", line 897, in __connect self.dbapi_connection = connection = pool._invoke_creator(self) ^^^^^^^^^^^^^^^^^^^^^^^^^^ File "/var/task/sqlalchemy/engine/create.py", line 646, in connect return dialect.connect(*cargs, **cparams) ^^^^^^^^^^^^^^^^^^^^^^^^^^^^^^^^^^ File "/var/task/sqlalchemy/engine/default.py", line 625, in connect return self.loaded_dbapi.connect(*cargs, **cparams) # type: ignore[no-any-return] # NOQA: E501 ^^^^^^^^^^^^^^^^^^^^^^^^^^^^^^^^^^^^^^^^^^^^ File "/var/task/psycopg2/__init__.py", line 122, in connect conn = _connect(dsn, connection_factory=connection_factory, **kwasync) ^^^^^^^^^^^^^^^^^^^^^^^^^^^^^^^^^^^^^^^^^^^^^^^^^^^^^^^^^^^^^^^ sqlalchemy.exc.OperationalError: (psycopg2.OperationalError) connection to server at "db.pjomptqavgnixbcoomvy.supabase.co" (2a05:d014:1c06:5f0f:d8b7:40ee:d73f:2bb2), port 5432 failed: Cannot assign requested address Is the server running on that host and accepting TCP/IP connections? (Background on this error at: https://sqlalche.me/e/20/e3q8) Python process exited with exit status: 1. The logs above can help with debugging the issue.
Apr 08 00:28:01.40
GET
500
last-x7uk3k9q6-mostafalol1233s-projects.vercel.app
/favicon.ico
ith_frames_removed File "/var/task/main.py", line 87, in <module> db.create_all() File "/var/task/flask_sqlalchemy/extension.py", line 900, in create_all self._call_for_binds(bind_key, "create_all") File "/var/task/flask_sqlalchemy/extension.py", line 881, in _call_for_binds getattr(metadata, op_name)(bind=engine) File "/var/task/sqlalchemy/sql/schema.py", line 5925, in create_all bind._run_ddl_visitor( File "/var/task/sqlalchemy/engine/base.py", line 3248, in _run_ddl_visitor with self.begin() as conn: ^^^^^^^^^^^^ File "/var/lang/lib/python3.12/contextlib.py", line 137, in __enter__ return next(self.gen) ^^^^^^^^^^^^^^ File "/var/task/sqlalchemy/engine/base.py", line 3238, in begin with self.connect() as conn: ^^^^^^^^^^^^^^ File "/var/task/sqlalchemy/engine/base.py", line 3274, in connect return self._connection_cls(self) ^^^^^^^^^^^^^^^^^^^^^^^^^^ File "/var/task/sqlalchemy/engine/base.py", line 148, in __init__ Connection._handle_dbapi_exception_noconnection( File "/var/task/sqlalchemy/engine/base.py", line 2439, in _handle_dbapi_exception_noconnection raise sqlalchemy_exception.with_traceback(exc_info[2]) from e File "/var/task/sqlalchemy/engine/base.py", line 146, in __init__ self._dbapi_connection = engine.raw_connection() ^^^^^^^^^^^^^^^^^^^^^^^ File "/var/task/sqlalchemy/engine/base.py", line 3298, in raw_connection return self.pool.connect() ^^^^^^^^^^^^^^^^^^^ File "/var/task/sqlalchemy/pool/base.py", line 449, in connect return _ConnectionFairy._checkout(self) ^^^^^^^^^^^^^^^^^^^^^^^^^^^^^^^^ File "/var/task/sqlalchemy/pool/base.py", line 1264, in _checkout fairy = _ConnectionRecord.checkout(pool) ^^^^^^^^^^^^^^^^^^^^^^^^^^^^^^^^ File "/var/task/sqlalchemy/pool/base.py", line 713, in checkout rec = pool._do_get() ^^^^^^^^^^^^^^ File "/var/task/sqlalchemy/pool/impl.py", line 179, in _do_get with util.safe_reraise(): ^^^^^^^^^^^^^^^^^^^ File "/var/task/sqlalchemy/util/langhelpers.py", line 146, in __exit__ raise exc_value.with_traceback(exc_tb) File "/var/task/sqlalchemy/pool/impl.py", line 177, in _do_get return self._create_connection() ^^^^^^^^^^^^^^^^^^^^^^^^^ File "/var/task/sqlalchemy/pool/base.py", line 390, in _create_connection return _ConnectionRecord(self) ^^^^^^^^^^^^^^^^^^^^^^^ File "/var/task/sqlalchemy/pool/base.py", line 675, in __init__ self.__connect() File "/var/task/sqlalchemy/pool/base.py", line 901, in __connect with util.safe_reraise(): ^^^^^^^^^^^^^^^^^^^ File "/var/task/sqlalchemy/util/langhelpers.py", line 146, in __exit__ raise exc_value.with_traceback(exc_tb) File "/var/task/sqlalchemy/pool/base.py", line 897, in __connect self.dbapi_connection = connection = pool._invoke_creator(self) ^^^^^^^^^^^^^^^^^^^^^^^^^^ File "/var/task/sqlalchemy/engine/create.py", line 646, in connect return dialect.connect(*cargs, **cparams) ^^^^^^^^^^^^^^^^^^^^^^^^^^^^^^^^^^ File "/var/task/sqlalchemy/engine/default.py", line 625, in connect return self.loaded_dbapi.connect(*cargs, **cparams) # type: ignore[no-any-return] # NOQA: E501 ^^^^^^^^^^^^^^^^^^^^^^^^^^^^^^^^^^^^^^^^^^^^ File "/var/task/psycopg2/__init__.py", line 122, in connect conn = _connect(dsn, connection_factory=connection_factory, **kwasync) ^^^^^^^^^^^^^^^^^^^^^^^^^^^^^^^^^^^^^^^^^^^^^^^^^^^^^^^^^^^^^^^ sqlalchemy.exc.OperationalError: (psycopg2.OperationalError) connection to server at "db.pjomptqavgnixbcoomvy.supabase.co" (2a05:d014:1c06:5f0f:d8b7:40ee:d73f:2bb2), port 5432 failed: Cannot assign requested address Is the server running on that host and accepting TCP/IP connections? (Background on this error at: https://sqlalche.me/e/20/e3q8) Python process exited with exit status: 1. The logs above can help with debugging the issue.
Apr 08 00:27:57.08
GET
500
last-x7uk3k9q6-mostafalol1233s-projects.vercel.app
/
ith_frames_removed File "/var/task/main.py", line 87, in <module> db.create_all() File "/var/task/flask_sqlalchemy/extension.py", line 900, in create_all self._call_for_binds(bind_key, "create_all") File "/var/task/flask_sqlalchemy/extension.py", line 881, in _call_for_binds getattr(metadata, op_name)(bind=engine) File "/var/task/sqlalchemy/sql/schema.py", line 5925, in create_all bind._run_ddl_visitor( File "/var/task/sqlalchemy/engine/base.py", line 3248, in _run_ddl_visitor with self.begin() as conn: ^^^^^^^^^^^^ File "/var/lang/lib/python3.12/contextlib.py", line 137, in __enter__ return next(self.gen) ^^^^^^^^^^^^^^ File "/var/task/sqlalchemy/engine/base.py", line 3238, in begin with self.connect() as conn: ^^^^^^^^^^^^^^ File "/var/task/sqlalchemy/engine/base.py", line 3274, in connect return self._connection_cls(self) ^^^^^^^^^^^^^^^^^^^^^^^^^^ File "/var/task/sqlalchemy/engine/base.py", line 148, in __init__ Connection._handle_dbapi_exception_noconnection( File "/var/task/sqlalchemy/engine/base.py", line 2439, in _handle_dbapi_exception_noconnection raise sqlalchemy_exception.with_traceback(exc_info[2]) from e File "/var/task/sqlalchemy/engine/base.py", line 146, in __init__ self._dbapi_connection = engine.raw_connection() ^^^^^^^^^^^^^^^^^^^^^^^ File "/var/task/sqlalchemy/engine/base.py", line 3298, in raw_connection return self.pool.connect() ^^^^^^^^^^^^^^^^^^^ File "/var/task/sqlalchemy/pool/base.py", line 449, in connect return _ConnectionFairy._checkout(self) ^^^^^^^^^^^^^^^^^^^^^^^^^^^^^^^^ File "/var/task/sqlalchemy/pool/base.py", line 1264, in _checkout fairy = _ConnectionRecord.checkout(pool) ^^^^^^^^^^^^^^^^^^^^^^^^^^^^^^^^ File "/var/task/sqlalchemy/pool/base.py", line 713, in checkout rec = pool._do_get() ^^^^^^^^^^^^^^ File "/var/task/sqlalchemy/pool/impl.py", line 179, in _do_get with util.safe_reraise(): ^^^^^^^^^^^^^^^^^^^ File "/var/task/sqlalchemy/util/langhelpers.py", line 146, in __exit__ raise exc_value.with_traceback(exc_tb) File "/var/task/sqlalchemy/pool/impl.py", line 177, in _do_get return self._create_connection() ^^^^^^^^^^^^^^^^^^^^^^^^^ File "/var/task/sqlalchemy/pool/base.py", line 390, in _create_connection return _ConnectionRecord(self) ^^^^^^^^^^^^^^^^^^^^^^^ File "/var/task/sqlalchemy/pool/base.py", line 675, in __init__ self.__connect() File "/var/task/sqlalchemy/pool/base.py", line 901, in __connect with util.safe_reraise(): ^^^^^^^^^^^^^^^^^^^ File "/var/task/sqlalchemy/util/langhelpers.py", line 146, in __exit__ raise exc_value.with_traceback(exc_tb) File "/var/task/sqlalchemy/pool/base.py", line 897, in __connect self.dbapi_connection = connection = pool._invoke_creator(self) ^^^^^^^^^^^^^^^^^^^^^^^^^^ File "/var/task/sqlalchemy/engine/create.py", line 646, in connect return dialect.connect(*cargs, **cparams) ^^^^^^^^^^^^^^^^^^^^^^^^^^^^^^^^^^ File "/var/task/sqlalchemy/engine/default.py", line 625, in connect return self.loaded_dbapi.connect(*cargs, **cparams) # type: ignore[no-any-return] # NOQA: E501 ^^^^^^^^^^^^^^^^^^^^^^^^^^^^^^^^^^^^^^^^^^^^ File "/var/task/psycopg2/__init__.py", line 122, in connect conn = _connect(dsn, connection_factory=connection_factory, **kwasync) ^^^^^^^^^^^^^^^^^^^^^^^^^^^^^^^^^^^^^^^^^^^^^^^^^^^^^^^^^^^^^^^ sqlalchemy.exc.OperationalError: (psycopg2.OperationalError) connection to server at "db.pjomptqavgnixbcoomvy.supabase.co" (2a05:d014:1c06:5f0f:d8b7:40ee:d73f:2bb2), port 5432 failed: Cannot assign requested address Is the server running on that host and accepting TCP/IP connections? (Background on this error at: https://sqlalche.me/e/20/e3q8) Python process exited with exit status: 1. The logs above can help with debugging the issue.
Apr 08 00:23:50.12
GET
500
last-x7uk3k9q6-mostafalol1233s-projects.vercel.app
/
ith_frames_removed File "/var/task/main.py", line 87, in <module> db.create_all() File "/var/task/flask_sqlalchemy/extension.py", line 900, in create_all self._call_for_binds(bind_key, "create_all") File "/var/task/flask_sqlalchemy/extension.py", line 881, in _call_for_binds getattr(metadata, op_name)(bind=engine) File "/var/task/sqlalchemy/sql/schema.py", line 5925, in create_all bind._run_ddl_visitor( File "/var/task/sqlalchemy/engine/base.py", line 3248, in _run_ddl_visitor with self.begin() as conn: ^^^^^^^^^^^^ File "/var/lang/lib/python3.12/contextlib.py", line 137, in __enter__ return next(self.gen) ^^^^^^^^^^^^^^ File "/var/task/sqlalchemy/engine/base.py", line 3238, in begin with self.connect() as conn: ^^^^^^^^^^^^^^ File "/var/task/sqlalchemy/engine/base.py", line 3274, in connect return self._connection_cls(self) ^^^^^^^^^^^^^^^^^^^^^^^^^^ File "/var/task/sqlalchemy/engine/base.py", line 148, in __init__ Connection._handle_dbapi_exception_noconnection( File "/var/task/sqlalchemy/engine/base.py", line 2439, in _handle_dbapi_exception_noconnection raise sqlalchemy_exception.with_traceback(exc_info[2]) from e File "/var/task/sqlalchemy/engine/base.py", line 146, in __init__ self._dbapi_connection = engine.raw_connection() ^^^^^^^^^^^^^^^^^^^^^^^ File "/var/task/sqlalchemy/engine/base.py", line 3298, in raw_connection return self.pool.connect() ^^^^^^^^^^^^^^^^^^^ File "/var/task/sqlalchemy/pool/base.py", line 449, in connect return _ConnectionFairy._checkout(self) ^^^^^^^^^^^^^^^^^^^^^^^^^^^^^^^^ File "/var/task/sqlalchemy/pool/base.py", line 1264, in _checkout fairy = _ConnectionRecord.checkout(pool) ^^^^^^^^^^^^^^^^^^^^^^^^^^^^^^^^ File "/var/task/sqlalchemy/pool/base.py", line 713, in checkout rec = pool._do_get() ^^^^^^^^^^^^^^ File "/var/task/sqlalchemy/pool/impl.py", line 179, in _do_get with util.safe_reraise(): ^^^^^^^^^^^^^^^^^^^ File "/var/task/sqlalchemy/util/langhelpers.py", line 146, in __exit__ raise exc_value.with_traceback(exc_tb) File "/var/task/sqlalchemy/pool/impl.py", line 177, in _do_get return self._create_connection() ^^^^^^^^^^^^^^^^^^^^^^^^^ File "/var/task/sqlalchemy/pool/base.py", line 390, in _create_connection return _ConnectionRecord(self) ^^^^^^^^^^^^^^^^^^^^^^^ File "/var/task/sqlalchemy/pool/base.py", line 675, in __init__ self.__connect() File "/var/task/sqlalchemy/pool/base.py", line 901, in __connect with util.safe_reraise(): ^^^^^^^^^^^^^^^^^^^ File "/var/task/sqlalchemy/util/langhelpers.py", line 146, in __exit__ raise exc_value.with_traceback(exc_tb) File "/var/task/sqlalchemy/pool/base.py", line 897, in __connect self.dbapi_connection = connection = pool._invoke_creator(self) ^^^^^^^^^^^^^^^^^^^^^^^^^^ File "/var/task/sqlalchemy/engine/create.py", line 646, in connect return dialect.connect(*cargs, **cparams) ^^^^^^^^^^^^^^^^^^^^^^^^^^^^^^^^^^ File "/var/task/sqlalchemy/engine/default.py", line 625, in connect return self.loaded_dbapi.connect(*cargs, **cparams) # type: ignore[no-any-return] # NOQA: E501 ^^^^^^^^^^^^^^^^^^^^^^^^^^^^^^^^^^^^^^^^^^^^ File "/var/task/psycopg2/__init__.py", line 122, in connect conn = _connect(dsn, connection_factory=connection_factory, **kwasync) ^^^^^^^^^^^^^^^^^^^^^^^^^^^^^^^^^^^^^^^^^^^^^^^^^^^^^^^^^^^^^^^ sqlalchemy.exc.OperationalError: (psycopg2.OperationalError) connection to server at "db.pjomptqavgnixbcoomvy.supabase.co" (2a05:d014:1c06:5f0f:d8b7:40ee:d73f:2bb2), port 5432 failed: Cannot assign requested address Is the server running on that host and accepting TCP/IP connections? (Background on this error at: https://sqlalche.me/e/20/e3q8) Python process exited with exit status: 1. The logs above can help with debugging the issue.
Apr 08 00:23:49.58
GET
500
last-x7uk3k9q6-mostafalol1233s-projects.vercel.app
/
ith_frames_removed File "/var/task/main.py", line 87, in <module> db.create_all() File "/var/task/flask_sqlalchemy/extension.py", line 900, in create_all self._call_for_binds(bind_key, "create_all") File "/var/task/flask_sqlalchemy/extension.py", line 881, in _call_for_binds getattr(metadata, op_name)(bind=engine) File "/var/task/sqlalchemy/sql/schema.py", line 5925, in create_all bind._run_ddl_visitor( File "/var/task/sqlalchemy/engine/base.py", line 3248, in _run_ddl_visitor with self.begin() as conn: ^^^^^^^^^^^^ File "/var/lang/lib/python3.12/contextlib.py", line 137, in __enter__ return next(self.gen) ^^^^^^^^^^^^^^ File "/var/task/sqlalchemy/engine/base.py", line 3238, in begin with self.connect() as conn: ^^^^^^^^^^^^^^ File "/var/task/sqlalchemy/engine/base.py", line 3274, in connect return self._connection_cls(self) ^^^^^^^^^^^^^^^^^^^^^^^^^^ File "/var/task/sqlalchemy/engine/base.py", line 148, in __init__ Connection._handle_dbapi_exception_noconnection( File "/var/task/sqlalchemy/engine/base.py", line 2439, in _handle_dbapi_exception_noconnection raise sqlalchemy_exception.with_traceback(exc_info[2]) from e File "/var/task/sqlalchemy/engine/base.py", line 146, in __init__ self._dbapi_connection = engine.raw_connection() ^^^^^^^^^^^^^^^^^^^^^^^ File "/var/task/sqlalchemy/engine/base.py", line 3298, in raw_connection return self.pool.connect() ^^^^^^^^^^^^^^^^^^^ File "/var/task/sqlalchemy/pool/base.py", line 449, in connect return _ConnectionFairy._checkout(self) ^^^^^^^^^^^^^^^^^^^^^^^^^^^^^^^^ File "/var/task/sqlalchemy/pool/base.py", line 1264, in _checkout fairy = _ConnectionRecord.checkout(pool) ^^^^^^^^^^^^^^^^^^^^^^^^^^^^^^^^ File "/var/task/sqlalchemy/pool/base.py", line 713, in checkout rec = pool._do_get() ^^^^^^^^^^^^^^ File "/var/task/sqlalchemy/pool/impl.py", line 179, in _do_get with util.safe_reraise(): ^^^^^^^^^^^^^^^^^^^ File "/var/task/sqlalchemy/util/langhelpers.py", line 146, in __exit__ raise exc_value.with_traceback(exc_tb) File "/var/task/sqlalchemy/pool/impl.py", line 177, in _do_get return self._create_connection() ^^^^^^^^^^^^^^^^^^^^^^^^^ File "/var/task/sqlalchemy/pool/base.py", line 390, in _create_connection return _ConnectionRecord(self) ^^^^^^^^^^^^^^^^^^^^^^^ File "/var/task/sqlalchemy/pool/base.py", line 675, in __init__ self.__connect() File "/var/task/sqlalchemy/pool/base.py", line 901, in __connect with util.safe_reraise(): ^^^^^^^^^^^^^^^^^^^ File "/var/task/sqlalchemy/util/langhelpers.py", line 146, in __exit__ raise exc_value.with_traceback(exc_tb) File "/var/task/sqlalchemy/pool/base.py", line 897, in __connect self.dbapi_connection = connection = pool._invoke_creator(self) ^^^^^^^^^^^^^^^^^^^^^^^^^^ File "/var/task/sqlalchemy/engine/create.py", line 646, in connect return dialect.connect(*cargs, **cparams) ^^^^^^^^^^^^^^^^^^^^^^^^^^^^^^^^^^ File "/var/task/sqlalchemy/engine/default.py", line 625, in connect return self.loaded_dbapi.connect(*cargs, **cparams) # type: ignore[no-any-return] # NOQA: E501 ^^^^^^^^^^^^^^^^^^^^^^^^^^^^^^^^^^^^^^^^^^^^ File "/var/task/psycopg2/__init__.py", line 122, in connect conn = _connect(dsn, connection_factory=connection_factory, **kwasync) ^^^^^^^^^^^^^^^^^^^^^^^^^^^^^^^^^^^^^^^^^^^^^^^^^^^^^^^^^^^^^^^ sqlalchemy.exc.OperationalError: (psycopg2.OperationalError) connection to server at "db.pjomptqavgnixbcoomvy.supabase.co" (2a05:d014:1c06:5f0f:d8b7:40ee:d73f:2bb2), port 5432 failed: Cannot assign requested address Is the server running on that host and accepting TCP/IP connections? (Background on this error at: https://sqlalche.me/e/20/e3q8) Python process exited with exit status: 1. The logs above can help with debugging the issue.
Apr 08 00:23:49.40
GET
500
last-x7uk3k9q6-mostafalol1233s-projects.vercel.app
/
ith_frames_removed File "/var/task/main.py", line 87, in <module> db.create_all() File "/var/task/flask_sqlalchemy/extension.py", line 900, in create_all self._call_for_binds(bind_key, "create_all") File "/var/task/flask_sqlalchemy/extension.py", line 881, in _call_for_binds getattr(metadata, op_name)(bind=engine) File "/var/task/sqlalchemy/sql/schema.py", line 5925, in create_all bind._run_ddl_visitor( File "/var/task/sqlalchemy/engine/base.py", line 3248, in _run_ddl_visitor with self.begin() as conn: ^^^^^^^^^^^^ File "/var/lang/lib/python3.12/contextlib.py", line 137, in __enter__ return next(self.gen) ^^^^^^^^^^^^^^ File "/var/task/sqlalchemy/engine/base.py", line 3238, in begin with self.connect() as conn: ^^^^^^^^^^^^^^ File "/var/task/sqlalchemy/engine/base.py", line 3274, in connect return self._connection_cls(self) ^^^^^^^^^^^^^^^^^^^^^^^^^^ File "/var/task/sqlalchemy/engine/base.py", line 148, in __init__ Connection._handle_dbapi_exception_noconnection( File "/var/task/sqlalchemy/engine/base.py", line 2439, in _handle_dbapi_exception_noconnection raise sqlalchemy_exception.with_traceback(exc_info[2]) from e File "/var/task/sqlalchemy/engine/base.py", line 146, in __init__ self._dbapi_connection = engine.raw_connection() ^^^^^^^^^^^^^^^^^^^^^^^ File "/var/task/sqlalchemy/engine/base.py", line 3298, in raw_connection return self.pool.connect() ^^^^^^^^^^^^^^^^^^^ File "/var/task/sqlalchemy/pool/base.py", line 449, in connect return _ConnectionFairy._checkout(self) ^^^^^^^^^^^^^^^^^^^^^^^^^^^^^^^^ File "/var/task/sqlalchemy/pool/base.py", line 1264, in _checkout fairy = _ConnectionRecord.checkout(pool) ^^^^^^^^^^^^^^^^^^^^^^^^^^^^^^^^ File "/var/task/sqlalchemy/pool/base.py", line 713, in checkout rec = pool._do_get() ^^^^^^^^^^^^^^ File "/var/task/sqlalchemy/pool/impl.py", line 179, in _do_get with util.safe_reraise(): ^^^^^^^^^^^^^^^^^^^ File "/var/task/sqlalchemy/util/langhelpers.py", line 146, in __exit__ raise exc_value.with_traceback(exc_tb) File "/var/task/sqlalchemy/pool/impl.py", line 177, in _do_get return self._create_connection() ^^^^^^^^^^^^^^^^^^^^^^^^^ File "/var/task/sqlalchemy/pool/base.py", line 390, in _create_connection return _ConnectionRecord(self) ^^^^^^^^^^^^^^^^^^^^^^^ File "/var/task/sqlalchemy/pool/base.py", line 675, in __init__ self.__connect() File "/var/task/sqlalchemy/pool/base.py", line 901, in __connect with util.safe_reraise(): ^^^^^^^^^^^^^^^^^^^ File "/var/task/sqlalchemy/util/langhelpers.py", line 146, in __exit__ raise exc_value.with_traceback(exc_tb) File "/var/task/sqlalchemy/pool/base.py", line 897, in __connect self.dbapi_connection = connection = pool._invoke_creator(self) ^^^^^^^^^^^^^^^^^^^^^^^^^^ File "/var/task/sqlalchemy/engine/create.py", line 646, in connect return dialect.connect(*cargs, **cparams) ^^^^^^^^^^^^^^^^^^^^^^^^^^^^^^^^^^ File "/var/task/sqlalchemy/engine/default.py", line 625, in connect return self.loaded_dbapi.connect(*cargs, **cparams) # type: ignore[no-any-return] # NOQA: E501 ^^^^^^^^^^^^^^^^^^^^^^^^^^^^^^^^^^^^^^^^^^^^ File "/var/task/psycopg2/__init__.py", line 122, in connect conn = _connect(dsn, connection_factory=connection_factory, **kwasync) ^^^^^^^^^^^^^^^^^^^^^^^^^^^^^^^^^^^^^^^^^^^^^^^^^^^^^^^^^^^^^^^ sqlalchemy.exc.OperationalError: (psycopg2.OperationalError) connection to server at "db.pjomptqavgnixbcoomvy.supabase.co" (2a05:d014:1c06:5f0f:d8b7:40ee:d73f:2bb2), port 5432 failed: Cannot assign requested address Is the server running on that host and accepting TCP/IP connections? (Background on this error at: https://sqlalche.me/e/20/e3q8) Python process exited with exit status: 1. The logs above can help with debugging the issue.
Apr 08 00:23:48.65
GET
500
last-x7uk3k9q6-mostafalol1233s-projects.vercel.app
/
ith_frames_removed File "/var/task/main.py", line 87, in <module> db.create_all() File "/var/task/flask_sqlalchemy/extension.py", line 900, in create_all self._call_for_binds(bind_key, "create_all") File "/var/task/flask_sqlalchemy/extension.py", line 881, in _call_for_binds getattr(metadata, op_name)(bind=engine) File "/var/task/sqlalchemy/sql/schema.py", line 5925, in create_all bind._run_ddl_visitor( File "/var/task/sqlalchemy/engine/base.py", line 3248, in _run_ddl_visitor with self.begin() as conn: ^^^^^^^^^^^^ File "/var/lang/lib/python3.12/contextlib.py", line 137, in __enter__ return next(self.gen) ^^^^^^^^^^^^^^ File "/var/task/sqlalchemy/engine/base.py", line 3238, in begin with self.connect() as conn: ^^^^^^^^^^^^^^ File "/var/task/sqlalchemy/engine/base.py", line 3274, in connect return self._connection_cls(self) ^^^^^^^^^^^^^^^^^^^^^^^^^^ File "/var/task/sqlalchemy/engine/base.py", line 148, in __init__ Connection._handle_dbapi_exception_noconnection( File "/var/task/sqlalchemy/engine/base.py", line 2439, in _handle_dbapi_exception_noconnection raise sqlalchemy_exception.with_traceback(exc_info[2]) from e File "/var/task/sqlalchemy/engine/base.py", line 146, in __init__ self._dbapi_connection = engine.raw_connection() ^^^^^^^^^^^^^^^^^^^^^^^ File "/var/task/sqlalchemy/engine/base.py", line 3298, in raw_connection return self.pool.connect() ^^^^^^^^^^^^^^^^^^^ File "/var/task/sqlalchemy/pool/base.py", line 449, in connect return _ConnectionFairy._checkout(self) ^^^^^^^^^^^^^^^^^^^^^^^^^^^^^^^^ File "/var/task/sqlalchemy/pool/base.py", line 1264, in _checkout fairy = _ConnectionRecord.checkout(pool) ^^^^^^^^^^^^^^^^^^^^^^^^^^^^^^^^ File "/var/task/sqlalchemy/pool/base.py", line 713, in checkout rec = pool._do_get() ^^^^^^^^^^^^^^ File "/var/task/sqlalchemy/pool/impl.py", line 179, in _do_get with util.safe_reraise(): ^^^^^^^^^^^^^^^^^^^ File "/var/task/sqlalchemy/util/langhelpers.py", line 146, in __exit__ raise exc_value.with_traceback(exc_tb) File "/var/task/sqlalchemy/pool/impl.py", line 177, in _do_get return self._create_connection() ^^^^^^^^^^^^^^^^^^^^^^^^^ File "/var/task/sqlalchemy/pool/base.py", line 390, in _create_connection return _ConnectionRecord(self) ^^^^^^^^^^^^^^^^^^^^^^^ File "/var/task/sqlalchemy/pool/base.py", line 675, in __init__ self.__connect() File "/var/task/sqlalchemy/pool/base.py", line 901, in __connect with util.safe_reraise(): ^^^^^^^^^^^^^^^^^^^ File "/var/task/sqlalchemy/util/langhelpers.py", line 146, in __exit__ raise exc_value.with_traceback(exc_tb) File "/var/task/sqlalchemy/pool/base.py", line 897, in __connect self.dbapi_connection = connection = pool._invoke_creator(self) ^^^^^^^^^^^^^^^^^^^^^^^^^^ File "/var/task/sqlalchemy/engine/create.py", line 646, in connect return dialect.connect(*cargs, **cparams) ^^^^^^^^^^^^^^^^^^^^^^^^^^^^^^^^^^ File "/var/task/sqlalchemy/engine/default.py", line 625, in connect return self.loaded_dbapi.connect(*cargs, **cparams) # type: ignore[no-any-return] # NOQA: E501 ^^^^^^^^^^^^^^^^^^^^^^^^^^^^^^^^^^^^^^^^^^^^ File "/var/task/psycopg2/__init__.py", line 122, in connect conn = _connect(dsn, connection_factory=connection_factory, **kwasync) ^^^^^^^^^^^^^^^^^^^^^^^^^^^^^^^^^^^^^^^^^^^^^^^^^^^^^^^^^^^^^^^ sqlalchemy.exc.OperationalError: (psycopg2.OperationalError) connection to server at "db.pjomptqavgnixbcoomvy.supabase.co" (2a05:d014:1c06:5f0f:d8b7:40ee:d73f:2bb2), port 5432 failed: Cannot assign requested address Is the server running on that host and accepting TCP/IP connections? (Background on this error at: https://sqlalche.me/e/20/e3q8) Python process exited with exit status: 1. The logs above can help with debugging the issue.
Apr 08 00:23:48.51
GET
500
last-x7uk3k9q6-mostafalol1233s-projects.vercel.app
/
ith_frames_removed File "/var/task/main.py", line 87, in <module> db.create_all() File "/var/task/flask_sqlalchemy/extension.py", line 900, in create_all self._call_for_binds(bind_key, "create_all") File "/var/task/flask_sqlalchemy/extension.py", line 881, in _call_for_binds getattr(metadata, op_name)(bind=engine) File "/var/task/sqlalchemy/sql/schema.py", line 5925, in create_all bind._run_ddl_visitor( File "/var/task/sqlalchemy/engine/base.py", line 3248, in _run_ddl_visitor with self.begin() as conn: ^^^^^^^^^^^^ File "/var/lang/lib/python3.12/contextlib.py", line 137, in __enter__ return next(self.gen) ^^^^^^^^^^^^^^ File "/var/task/sqlalchemy/engine/base.py", line 3238, in begin with self.connect() as conn: ^^^^^^^^^^^^^^ File "/var/task/sqlalchemy/engine/base.py", line 3274, in connect return self._connection_cls(self) ^^^^^^^^^^^^^^^^^^^^^^^^^^ File "/var/task/sqlalchemy/engine/base.py", line 148, in __init__ Connection._handle_dbapi_exception_noconnection( File "/var/task/sqlalchemy/engine/base.py", line 2439, in _handle_dbapi_exception_noconnection raise sqlalchemy_exception.with_traceback(exc_info[2]) from e File "/var/task/sqlalchemy/engine/base.py", line 146, in __init__ self._dbapi_connection = engine.raw_connection() ^^^^^^^^^^^^^^^^^^^^^^^ File "/var/task/sqlalchemy/engine/base.py", line 3298, in raw_connection return self.pool.connect() ^^^^^^^^^^^^^^^^^^^ File "/var/task/sqlalchemy/pool/base.py", line 449, in connect return _ConnectionFairy._checkout(self) ^^^^^^^^^^^^^^^^^^^^^^^^^^^^^^^^ File "/var/task/sqlalchemy/pool/base.py", line 1264, in _checkout fairy = _ConnectionRecord.checkout(pool) ^^^^^^^^^^^^^^^^^^^^^^^^^^^^^^^^ File "/var/task/sqlalchemy/pool/base.py", line 713, in checkout rec = pool._do_get() ^^^^^^^^^^^^^^ File "/var/task/sqlalchemy/pool/impl.py", line 179, in _do_get with util.safe_reraise(): ^^^^^^^^^^^^^^^^^^^ File "/var/task/sqlalchemy/util/langhelpers.py", line 146, in __exit__ raise exc_value.with_traceback(exc_tb) File "/var/task/sqlalchemy/pool/impl.py", line 177, in _do_get return self._create_connection() ^^^^^^^^^^^^^^^^^^^^^^^^^ File "/var/task/sqlalchemy/pool/base.py", line 390, in _create_connection return _ConnectionRecord(self) ^^^^^^^^^^^^^^^^^^^^^^^ File "/var/task/sqlalchemy/pool/base.py", line 675, in __init__ self.__connect() File "/var/task/sqlalchemy/pool/base.py", line 901, in __connect with util.safe_reraise(): ^^^^^^^^^^^^^^^^^^^ File "/var/task/sqlalchemy/util/langhelpers.py", line 146, in __exit__ raise exc_value.with_traceback(exc_tb) File "/var/task/sqlalchemy/pool/base.py", line 897, in __connect self.dbapi_connection = connection = pool._invoke_creator(self) ^^^^^^^^^^^^^^^^^^^^^^^^^^ File "/var/task/sqlalchemy/engine/create.py", line 646, in connect return dialect.connect(*cargs, **cparams) ^^^^^^^^^^^^^^^^^^^^^^^^^^^^^^^^^^ File "/var/task/sqlalchemy/engine/default.py", line 625, in connect return self.loaded_dbapi.connect(*cargs, **cparams) # type: ignore[no-any-return] # NOQA: E501 ^^^^^^^^^^^^^^^^^^^^^^^^^^^^^^^^^^^^^^^^^^^^ File "/var/task/psycopg2/__init__.py", line 122, in connect conn = _connect(dsn, connection_factory=connection_factory, **kwasync) ^^^^^^^^^^^^^^^^^^^^^^^^^^^^^^^^^^^^^^^^^^^^^^^^^^^^^^^^^^^^^^^ sqlalchemy.exc.OperationalError: (psycopg2.OperationalError) connection to server at "db.pjomptqavgnixbcoomvy.supabase.co" (2a05:d014:1c06:5f0f:d8b7:40ee:d73f:2bb2), port 5432 failed: Cannot assign requested address Is the server running on that host and accepting TCP/IP connections? (Background on this error at: https://sqlalche.me/e/20/e3q8) Python process exited with exit status: 1. The logs above can help with debugging the issue.
Apr 08 00:23:43.92
GET
500
last-x7uk3k9q6-mostafalol1233s-projects.vercel.app
/
ith_frames_removed File "/var/task/main.py", line 87, in <module> db.create_all() File "/var/task/flask_sqlalchemy/extension.py", line 900, in create_all self._call_for_binds(bind_key, "create_all") File "/var/task/flask_sqlalchemy/extension.py", line 881, in _call_for_binds getattr(metadata, op_name)(bind=engine) File "/var/task/sqlalchemy/sql/schema.py", line 5925, in create_all bind._run_ddl_visitor( File "/var/task/sqlalchemy/engine/base.py", line 3248, in _run_ddl_visitor with self.begin() as conn: ^^^^^^^^^^^^ File "/var/lang/lib/python3.12/contextlib.py", line 137, in __enter__ return next(self.gen) ^^^^^^^^^^^^^^ File "/var/task/sqlalchemy/engine/base.py", line 3238, in begin with self.connect() as conn: ^^^^^^^^^^^^^^ File "/var/task/sqlalchemy/engine/base.py", line 3274, in connect return self._connection_cls(self) ^^^^^^^^^^^^^^^^^^^^^^^^^^ File "/var/task/sqlalchemy/engine/base.py", line 148, in __init__ Connection._handle_dbapi_exception_noconnection( File "/var/task/sqlalchemy/engine/base.py", line 2439, in _handle_dbapi_exception_noconnection raise sqlalchemy_exception.with_traceback(exc_info[2]) from e File "/var/task/sqlalchemy/engine/base.py", line 146, in __init__ self._dbapi_connection = engine.raw_connection() ^^^^^^^^^^^^^^^^^^^^^^^ File "/var/task/sqlalchemy/engine/base.py", line 3298, in raw_connection return self.pool.connect() ^^^^^^^^^^^^^^^^^^^ File "/var/task/sqlalchemy/pool/base.py", line 449, in connect return _ConnectionFairy._checkout(self) ^^^^^^^^^^^^^^^^^^^^^^^^^^^^^^^^ File "/var/task/sqlalchemy/pool/base.py", line 1264, in _checkout fairy = _ConnectionRecord.checkout(pool) ^^^^^^^^^^^^^^^^^^^^^^^^^^^^^^^^ File "/var/task/sqlalchemy/pool/base.py", line 713, in checkout rec = pool._do_get() ^^^^^^^^^^^^^^ File "/var/task/sqlalchemy/pool/impl.py", line 179, in _do_get with util.safe_reraise(): ^^^^^^^^^^^^^^^^^^^ File "/var/task/sqlalchemy/util/langhelpers.py", line 146, in __exit__ raise exc_value.with_traceback(exc_tb) File "/var/task/sqlalchemy/pool/impl.py", line 177, in _do_get return self._create_connection() ^^^^^^^^^^^^^^^^^^^^^^^^^ File "/var/task/sqlalchemy/pool/base.py", line 390, in _create_connection return _ConnectionRecord(self) ^^^^^^^^^^^^^^^^^^^^^^^ File "/var/task/sqlalchemy/pool/base.py", line 675, in __init__ self.__connect() File "/var/task/sqlalchemy/pool/base.py", line 901, in __connect with util.safe_reraise(): ^^^^^^^^^^^^^^^^^^^ File "/var/task/sqlalchemy/util/langhelpers.py", line 146, in __exit__ raise exc_value.with_traceback(exc_tb) File "/var/task/sqlalchemy/pool/base.py", line 897, in __connect self.dbapi_connection = connection = pool._invoke_creator(self) ^^^^^^^^^^^^^^^^^^^^^^^^^^ File "/var/task/sqlalchemy/engine/create.py", line 646, in connect return dialect.connect(*cargs, **cparams) ^^^^^^^^^^^^^^^^^^^^^^^^^^^^^^^^^^ File "/var/task/sqlalchemy/engine/default.py", line 625, in connect return self.loaded_dbapi.connect(*cargs, **cparams) # type: ignore[no-any-return] # NOQA: E501 ^^^^^^^^^^^^^^^^^^^^^^^^^^^^^^^^^^^^^^^^^^^^ File "/var/task/psycopg2/__init__.py", line 122, in connect conn = _connect(dsn, connection_factory=connection_factory, **kwasync) ^^^^^^^^^^^^^^^^^^^^^^^^^^^^^^^^^^^^^^^^^^^^^^^^^^^^^^^^^^^^^^^ sqlalchemy.exc.OperationalError: (psycopg2.OperationalError) connection to server at "db.pjomptqavgnixbcoomvy.supabase.co" (2a05:d014:1c06:5f0f:d8b7:40ee:d73f:2bb2), port 5432 failed: Cannot assign requested address Is the server running on that host and accepting TCP/IP connections? (Background on this error at: https://sqlalche.me/e/20/e3q8) Python process exited with exit status: 1. The logs above can help with debugging the issue.
Apr 08 00:23:43.42
GET
500
last-x7uk3k9q6-mostafalol1233s-projects.vercel.app
/
ith_frames_removed File "/var/task/main.py", line 87, in <module> db.create_all() File "/var/task/flask_sqlalchemy/extension.py", line 900, in create_all self._call_for_binds(bind_key, "create_all") File "/var/task/flask_sqlalchemy/extension.py", line 881, in _call_for_binds getattr(metadata, op_name)(bind=engine) File "/var/task/sqlalchemy/sql/schema.py", line 5925, in create_all bind._run_ddl_visitor( File "/var/task/sqlalchemy/engine/base.py", line 3248, in _run_ddl_visitor with self.begin() as conn: ^^^^^^^^^^^^ File "/var/lang/lib/python3.12/contextlib.py", line 137, in __enter__ return next(self.gen) ^^^^^^^^^^^^^^ File "/var/task/sqlalchemy/engine/base.py", line 3238, in begin with self.connect() as conn: ^^^^^^^^^^^^^^ File "/var/task/sqlalchemy/engine/base.py", line 3274, in connect return self._connection_cls(self) ^^^^^^^^^^^^^^^^^^^^^^^^^^ File "/var/task/sqlalchemy/engine/base.py", line 148, in __init__ Connection._handle_dbapi_exception_noconnection( File "/var/task/sqlalchemy/engine/base.py", line 2439, in _handle_dbapi_exception_noconnection raise sqlalchemy_exception.with_traceback(exc_info[2]) from e File "/var/task/sqlalchemy/engine/base.py", line 146, in __init__ self._dbapi_connection = engine.raw_connection() ^^^^^^^^^^^^^^^^^^^^^^^ File "/var/task/sqlalchemy/engine/base.py", line 3298, in raw_connection return self.pool.connect() ^^^^^^^^^^^^^^^^^^^ File "/var/task/sqlalchemy/pool/base.py", line 449, in connect return _ConnectionFairy._checkout(self) ^^^^^^^^^^^^^^^^^^^^^^^^^^^^^^^^ File "/var/task/sqlalchemy/pool/base.py", line 1264, in _checkout fairy = _ConnectionRecord.checkout(pool) ^^^^^^^^^^^^^^^^^^^^^^^^^^^^^^^^ File "/var/task/sqlalchemy/pool/base.py", line 713, in checkout rec = pool._do_get() ^^^^^^^^^^^^^^ File "/var/task/sqlalchemy/pool/impl.py", line 179, in _do_get with util.safe_reraise(): ^^^^^^^^^^^^^^^^^^^ File "/var/task/sqlalchemy/util/langhelpers.py", line 146, in __exit__ raise exc_value.with_traceback(exc_tb) File "/var/task/sqlalchemy/pool/impl.py", line 177, in _do_get return self._create_connection() ^^^^^^^^^^^^^^^^^^^^^^^^^ File "/var/task/sqlalchemy/pool/base.py", line 390, in _create_connection return _ConnectionRecord(self) ^^^^^^^^^^^^^^^^^^^^^^^ File "/var/task/sqlalchemy/pool/base.py", line 675, in __init__ self.__connect() File "/var/task/sqlalchemy/pool/base.py", line 901, in __connect with util.safe_reraise(): ^^^^^^^^^^^^^^^^^^^ File "/var/task/sqlalchemy/util/langhelpers.py", line 146, in __exit__ raise exc_value.with_traceback(exc_tb) File "/var/task/sqlalchemy/pool/base.py", line 897, in __connect self.dbapi_connection = connection = pool._invoke_creator(self) ^^^^^^^^^^^^^^^^^^^^^^^^^^ File "/var/task/sqlalchemy/engine/create.py", line 646, in connect return dialect.connect(*cargs, **cparams) ^^^^^^^^^^^^^^^^^^^^^^^^^^^^^^^^^^ File "/var/task/sqlalchemy/engine/default.py", line 625, in connect return self.loaded_dbapi.connect(*cargs, **cparams) # type: ignore[no-any-return] # NOQA: E501 ^^^^^^^^^^^^^^^^^^^^^^^^^^^^^^^^^^^^^^^^^^^^ File "/var/task/psycopg2/__init__.py", line 122, in connect conn = _connect(dsn, connection_factory=connection_factory, **kwasync) ^^^^^^^^^^^^^^^^^^^^^^^^^^^^^^^^^^^^^^^^^^^^^^^^^^^^^^^^^^^^^^^ sqlalchemy.exc.OperationalError: (psycopg2.OperationalError) connection to server at "db.pjomptqavgnixbcoomvy.supabase.co" (2a05:d014:1c06:5f0f:d8b7:40ee:d73f:2bb2), port 5432 failed: Cannot assign requested address Is the server running on that host and accepting TCP/IP connections? (Background on this error at: https://sqlalche.me/e/20/e3q8) Python process exited with exit status: 1. The logs above can help with debugging the issue.
Apr 08 00:23:43.31
GET
500
last-x7uk3k9q6-mostafalol1233s-projects.vercel.app
/
ith_frames_removed File "/var/task/main.py", line 87, in <module> db.create_all() File "/var/task/flask_sqlalchemy/extension.py", line 900, in create_all self._call_for_binds(bind_key, "create_all") File "/var/task/flask_sqlalchemy/extension.py", line 881, in _call_for_binds getattr(metadata, op_name)(bind=engine) File "/var/task/sqlalchemy/sql/schema.py", line 5925, in create_all bind._run_ddl_visitor( File "/var/task/sqlalchemy/engine/base.py", line 3248, in _run_ddl_visitor with self.begin() as conn: ^^^^^^^^^^^^ File "/var/lang/lib/python3.12/contextlib.py", line 137, in __enter__ return next(self.gen) ^^^^^^^^^^^^^^ File "/var/task/sqlalchemy/engine/base.py", line 3238, in begin with self.connect() as conn: ^^^^^^^^^^^^^^ File "/var/task/sqlalchemy/engine/base.py", line 3274, in connect return self._connection_cls(self) ^^^^^^^^^^^^^^^^^^^^^^^^^^ File "/var/task/sqlalchemy/engine/base.py", line 148, in __init__ Connection._handle_dbapi_exception_noconnection( File "/var/task/sqlalchemy/engine/base.py", line 2439, in _handle_dbapi_exception_noconnection raise sqlalchemy_exception.with_traceback(exc_info[2]) from e File "/var/task/sqlalchemy/engine/base.py", line 146, in __init__ self._dbapi_connection = engine.raw_connection() ^^^^^^^^^^^^^^^^^^^^^^^ File "/var/task/sqlalchemy/engine/base.py", line 3298, in raw_connection return self.pool.connect() ^^^^^^^^^^^^^^^^^^^ File "/var/task/sqlalchemy/pool/base.py", line 449, in connect return _ConnectionFairy._checkout(self) ^^^^^^^^^^^^^^^^^^^^^^^^^^^^^^^^ File "/var/task/sqlalchemy/pool/base.py", line 1264, in _checkout fairy = _ConnectionRecord.checkout(pool) ^^^^^^^^^^^^^^^^^^^^^^^^^^^^^^^^ File "/var/task/sqlalchemy/pool/base.py", line 713, in checkout rec = pool._do_get() ^^^^^^^^^^^^^^ File "/var/task/sqlalchemy/pool/impl.py", line 179, in _do_get with util.safe_reraise(): ^^^^^^^^^^^^^^^^^^^ File "/var/task/sqlalchemy/util/langhelpers.py", line 146, in __exit__ raise exc_value.with_traceback(exc_tb) File "/var/task/sqlalchemy/pool/impl.py", line 177, in _do_get return self._create_connection() ^^^^^^^^^^^^^^^^^^^^^^^^^ File "/var/task/sqlalchemy/pool/base.py", line 390, in _create_connection return _ConnectionRecord(self) ^^^^^^^^^^^^^^^^^^^^^^^ File "/var/task/sqlalchemy/pool/base.py", line 675, in __init__ self.__connect() File "/var/task/sqlalchemy/pool/base.py", line 901, in __connect with util.safe_reraise(): ^^^^^^^^^^^^^^^^^^^ File "/var/task/sqlalchemy/util/langhelpers.py", line 146, in __exit__ raise exc_value.with_traceback(exc_tb) File "/var/task/sqlalchemy/pool/base.py", line 897, in __connect self.dbapi_connection = connection = pool._invoke_creator(self) ^^^^^^^^^^^^^^^^^^^^^^^^^^ File "/var/task/sqlalchemy/engine/create.py", line 646, in connect return dialect.connect(*cargs, **cparams) ^^^^^^^^^^^^^^^^^^^^^^^^^^^^^^^^^^ File "/var/task/sqlalchemy/engine/default.py", line 625, in connect return self.loaded_dbapi.connect(*cargs, **cparams) # type: ignore[no-any-return] # NOQA: E501 ^^^^^^^^^^^^^^^^^^^^^^^^^^^^^^^^^^^^^^^^^^^^ File "/var/task/psycopg2/__init__.py", line 122, in connect conn = _connect(dsn, connection_factory=connection_factory, **kwasync) ^^^^^^^^^^^^^^^^^^^^^^^^^^^^^^^^^^^^^^^^^^^^^^^^^^^^^^^^^^^^^^^ sqlalchemy.exc.OperationalError: (psycopg2.OperationalError) connection to server at "db.pjomptqavgnixbcoomvy.supabase.co" (2a05:d014:1c06:5f0f:d8b7:40ee:d73f:2bb2), port 5432 failed: Cannot assign requested address Is the server running on that host and accepting TCP/IP connections? (Background on this error at: https://sqlalche.me/e/20/e3q8) Python process exited with exit status: 1. The logs above can help with debugging the issue.
Apr 08 00:23:42.46
GET
500
last-x7uk3k9q6-mostafalol1233s-projects.vercel.app
/
ith_frames_removed File "/var/task/main.py", line 87, in <module> db.create_all() File "/var/task/flask_sqlalchemy/extension.py", line 900, in create_all self._call_for_binds(bind_key, "create_all") File "/var/task/flask_sqlalchemy/extension.py", line 881, in _call_for_binds getattr(metadata, op_name)(bind=engine) File "/var/task/sqlalchemy/sql/schema.py", line 5925, in create_all bind._run_ddl_visitor( File "/var/task/sqlalchemy/engine/base.py", line 3248, in _run_ddl_visitor with self.begin() as conn: ^^^^^^^^^^^^ File "/var/lang/lib/python3.12/contextlib.py", line 137, in __enter__ return next(self.gen) ^^^^^^^^^^^^^^ File "/var/task/sqlalchemy/engine/base.py", line 3238, in begin with self.connect() as conn: ^^^^^^^^^^^^^^ File "/var/task/sqlalchemy/engine/base.py", line 3274, in connect return self._connection_cls(self) ^^^^^^^^^^^^^^^^^^^^^^^^^^ File "/var/task/sqlalchemy/engine/base.py", line 148, in __init__ Connection._handle_dbapi_exception_noconnection( File "/var/task/sqlalchemy/engine/base.py", line 2439, in _handle_dbapi_exception_noconnection raise sqlalchemy_exception.with_traceback(exc_info[2]) from e File "/var/task/sqlalchemy/engine/base.py", line 146, in __init__ self._dbapi_connection = engine.raw_connection() ^^^^^^^^^^^^^^^^^^^^^^^ File "/var/task/sqlalchemy/engine/base.py", line 3298, in raw_connection return self.pool.connect() ^^^^^^^^^^^^^^^^^^^ File "/var/task/sqlalchemy/pool/base.py", line 449, in connect return _ConnectionFairy._checkout(self) ^^^^^^^^^^^^^^^^^^^^^^^^^^^^^^^^ File "/var/task/sqlalchemy/pool/base.py", line 1264, in _checkout fairy = _ConnectionRecord.checkout(pool) ^^^^^^^^^^^^^^^^^^^^^^^^^^^^^^^^ File "/var/task/sqlalchemy/pool/base.py", line 713, in checkout rec = pool._do_get() ^^^^^^^^^^^^^^ File "/var/task/sqlalchemy/pool/impl.py", line 179, in _do_get with util.safe_reraise(): ^^^^^^^^^^^^^^^^^^^ File "/var/task/sqlalchemy/util/langhelpers.py", line 146, in __exit__ raise exc_value.with_traceback(exc_tb) File "/var/task/sqlalchemy/pool/impl.py", line 177, in _do_get return self._create_connection() ^^^^^^^^^^^^^^^^^^^^^^^^^ File "/var/task/sqlalchemy/pool/base.py", line 390, in _create_connection return _ConnectionRecord(self) ^^^^^^^^^^^^^^^^^^^^^^^ File "/var/task/sqlalchemy/pool/base.py", line 675, in __init__ self.__connect() File "/var/task/sqlalchemy/pool/base.py", line 901, in __connect with util.safe_reraise(): ^^^^^^^^^^^^^^^^^^^ File "/var/task/sqlalchemy/util/langhelpers.py", line 146, in __exit__ raise exc_value.with_traceback(exc_tb) File "/var/task/sqlalchemy/pool/base.py", line 897, in __connect self.dbapi_connection = connection = pool._invoke_creator(self) ^^^^^^^^^^^^^^^^^^^^^^^^^^ File "/var/task/sqlalchemy/engine/create.py", line 646, in connect return dialect.connect(*cargs, **cparams) ^^^^^^^^^^^^^^^^^^^^^^^^^^^^^^^^^^ File "/var/task/sqlalchemy/engine/default.py", line 625, in connect return self.loaded_dbapi.connect(*cargs, **cparams) # type: ignore[no-any-return] # NOQA: E501 ^^^^^^^^^^^^^^^^^^^^^^^^^^^^^^^^^^^^^^^^^^^^ File "/var/task/psycopg2/__init__.py", line 122, in connect conn = _connect(dsn, connection_factory=connection_factory, **kwasync) ^^^^^^^^^^^^^^^^^^^^^^^^^^^^^^^^^^^^^^^^^^^^^^^^^^^^^^^^^^^^^^^ sqlalchemy.exc.OperationalError: (psycopg2.OperationalError) connection to server at "db.pjomptqavgnixbcoomvy.supabase.co" (2a05:d014:1c06:5f0f:d8b7:40ee:d73f:2bb2), port 5432 failed: Cannot assign requested address Is the server running on that host and accepting TCP/IP connections? (Background on this error at: https://sqlalche.me/e/20/e3q8) Python process exited with exit status: 1. The logs above can help with debugging the issue.
Apr 08 00:23:42.40
GET
500
last-x7uk3k9q6-mostafalol1233s-projects.vercel.app
/
ith_frames_removed File "/var/task/main.py", line 87, in <module> db.create_all() File "/var/task/flask_sqlalchemy/extension.py", line 900, in create_all self._call_for_binds(bind_key, "create_all") File "/var/task/flask_sqlalchemy/extension.py", line 881, in _call_for_binds getattr(metadata, op_name)(bind=engine) File "/var/task/sqlalchemy/sql/schema.py", line 5925, in create_all bind._run_ddl_visitor( File "/var/task/sqlalchemy/engine/base.py", line 3248, in _run_ddl_visitor with self.begin() as conn: ^^^^^^^^^^^^ File "/var/lang/lib/python3.12/contextlib.py", line 137, in __enter__ return next(self.gen) ^^^^^^^^^^^^^^ File "/var/task/sqlalchemy/engine/base.py", line 3238, in begin with self.connect() as conn: ^^^^^^^^^^^^^^ File "/var/task/sqlalchemy/engine/base.py", line 3274, in connect return self._connection_cls(self) ^^^^^^^^^^^^^^^^^^^^^^^^^^ File "/var/task/sqlalchemy/engine/base.py", line 148, in __init__ Connection._handle_dbapi_exception_noconnection( File "/var/task/sqlalchemy/engine/base.py", line 2439, in _handle_dbapi_exception_noconnection raise sqlalchemy_exception.with_traceback(exc_info[2]) from e File "/var/task/sqlalchemy/engine/base.py", line 146, in __init__ self._dbapi_connection = engine.raw_connection() ^^^^^^^^^^^^^^^^^^^^^^^ File "/var/task/sqlalchemy/engine/base.py", line 3298, in raw_connection return self.pool.connect() ^^^^^^^^^^^^^^^^^^^ File "/var/task/sqlalchemy/pool/base.py", line 449, in connect return _ConnectionFairy._checkout(self) ^^^^^^^^^^^^^^^^^^^^^^^^^^^^^^^^ File "/var/task/sqlalchemy/pool/base.py", line 1264, in _checkout fairy = _ConnectionRecord.checkout(pool) ^^^^^^^^^^^^^^^^^^^^^^^^^^^^^^^^ File "/var/task/sqlalchemy/pool/base.py", line 713, in checkout rec = pool._do_get() ^^^^^^^^^^^^^^ File "/var/task/sqlalchemy/pool/impl.py", line 179, in _do_get with util.safe_reraise(): ^^^^^^^^^^^^^^^^^^^ File "/var/task/sqlalchemy/util/langhelpers.py", line 146, in __exit__ raise exc_value.with_traceback(exc_tb) File "/var/task/sqlalchemy/pool/impl.py", line 177, in _do_get return self._create_connection() ^^^^^^^^^^^^^^^^^^^^^^^^^ File "/var/task/sqlalchemy/pool/base.py", line 390, in _create_connection return _ConnectionRecord(self) ^^^^^^^^^^^^^^^^^^^^^^^ File "/var/task/sqlalchemy/pool/base.py", line 675, in __init__ self.__connect() File "/var/task/sqlalchemy/pool/base.py", line 901, in __connect with util.safe_reraise(): ^^^^^^^^^^^^^^^^^^^ File "/var/task/sqlalchemy/util/langhelpers.py", line 146, in __exit__ raise exc_value.with_traceback(exc_tb) File "/var/task/sqlalchemy/pool/base.py", line 897, in __connect self.dbapi_connection = connection = pool._invoke_creator(self) ^^^^^^^^^^^^^^^^^^^^^^^^^^ File "/var/task/sqlalchemy/engine/create.py", line 646, in connect return dialect.connect(*cargs, **cparams) ^^^^^^^^^^^^^^^^^^^^^^^^^^^^^^^^^^ File "/var/task/sqlalchemy/engine/default.py", line 625, in connect return self.loaded_dbapi.connect(*cargs, **cparams) # type: ignore[no-any-return] # NOQA: E501 ^^^^^^^^^^^^^^^^^^^^^^^^^^^^^^^^^^^^^^^^^^^^ File "/var/task/psycopg2/__init__.py", line 122, in connect conn = _connect(dsn, connection_factory=connection_factory, **kwasync) ^^^^^^^^^^^^^^^^^^^^^^^^^^^^^^^^^^^^^^^^^^^^^^^^^^^^^^^^^^^^^^^ sqlalchemy.exc.OperationalError: (psycopg2.OperationalError) connection to server at "db.pjomptqavgnixbcoomvy.supabase.co" (2a05:d014:1c06:5f0f:d8b7:40ee:d73f:2bb2), port 5432 failed: Cannot assign requested address Is the server running on that host and accepting TCP/IP connections? (Background on this error at: https://sqlalche.me/e/20/e3q8) Python process exited with exit status: 1. The logs above can help with debugging the issue.
Apr 08 00:23:37.99
GET
500
last-x7uk3k9q6-mostafalol1233s-projects.vercel.app
/
ith_frames_removed File "/var/task/main.py", line 87, in <module> db.create_all() File "/var/task/flask_sqlalchemy/extension.py", line 900, in create_all self._call_for_binds(bind_key, "create_all") File "/var/task/flask_sqlalchemy/extension.py", line 881, in _call_for_binds getattr(metadata, op_name)(bind=engine) File "/var/task/sqlalchemy/sql/schema.py", line 5925, in create_all bind._run_ddl_visitor( File "/var/task/sqlalchemy/engine/base.py", line 3248, in _run_ddl_visitor with self.begin() as conn: ^^^^^^^^^^^^ File "/var/lang/lib/python3.12/contextlib.py", line 137, in __enter__ return next(self.gen) ^^^^^^^^^^^^^^ File "/var/task/sqlalchemy/engine/base.py", line 3238, in begin with self.connect() as conn: ^^^^^^^^^^^^^^ File "/var/task/sqlalchemy/engine/base.py", line 3274, in connect return self._connection_cls(self) ^^^^^^^^^^^^^^^^^^^^^^^^^^ File "/var/task/sqlalchemy/engine/base.py", line 148, in __init__ Connection._handle_dbapi_exception_noconnection( File "/var/task/sqlalchemy/engine/base.py", line 2439, in _handle_dbapi_exception_noconnection raise sqlalchemy_exception.with_traceback(exc_info[2]) from e File "/var/task/sqlalchemy/engine/base.py", line 146, in __init__ self._dbapi_connection = engine.raw_connection() ^^^^^^^^^^^^^^^^^^^^^^^ File "/var/task/sqlalchemy/engine/base.py", line 3298, in raw_connection return self.pool.connect() ^^^^^^^^^^^^^^^^^^^ File "/var/task/sqlalchemy/pool/base.py", line 449, in connect return _ConnectionFairy._checkout(self) ^^^^^^^^^^^^^^^^^^^^^^^^^^^^^^^^ File "/var/task/sqlalchemy/pool/base.py", line 1264, in _checkout fairy = _ConnectionRecord.checkout(pool) ^^^^^^^^^^^^^^^^^^^^^^^^^^^^^^^^ File "/var/task/sqlalchemy/pool/base.py", line 713, in checkout rec = pool._do_get() ^^^^^^^^^^^^^^ File "/var/task/sqlalchemy/pool/impl.py", line 179, in _do_get with util.safe_reraise(): ^^^^^^^^^^^^^^^^^^^ File "/var/task/sqlalchemy/util/langhelpers.py", line 146, in __exit__ raise exc_value.with_traceback(exc_tb) File "/var/task/sqlalchemy/pool/impl.py", line 177, in _do_get return self._create_connection() ^^^^^^^^^^^^^^^^^^^^^^^^^ File "/var/task/sqlalchemy/pool/base.py", line 390, in _create_connection return _ConnectionRecord(self) ^^^^^^^^^^^^^^^^^^^^^^^ File "/var/task/sqlalchemy/pool/base.py", line 675, in __init__ self.__connect() File "/var/task/sqlalchemy/pool/base.py", line 901, in __connect with util.safe_reraise(): ^^^^^^^^^^^^^^^^^^^ File "/var/task/sqlalchemy/util/langhelpers.py", line 146, in __exit__ raise exc_value.with_traceback(exc_tb) File "/var/task/sqlalchemy/pool/base.py", line 897, in __connect self.dbapi_connection = connection = pool._invoke_creator(self) ^^^^^^^^^^^^^^^^^^^^^^^^^^ File "/var/task/sqlalchemy/engine/create.py", line 646, in connect return dialect.connect(*cargs, **cparams) ^^^^^^^^^^^^^^^^^^^^^^^^^^^^^^^^^^ File "/var/task/sqlalchemy/engine/default.py", line 625, in connect return self.loaded_dbapi.connect(*cargs, **cparams) # type: ignore[no-any-return] # NOQA: E501 ^^^^^^^^^^^^^^^^^^^^^^^^^^^^^^^^^^^^^^^^^^^^ File "/var/task/psycopg2/__init__.py", line 122, in connect conn = _connect(dsn, connection_factory=connection_factory, **kwasync) ^^^^^^^^^^^^^^^^^^^^^^^^^^^^^^^^^^^^^^^^^^^^^^^^^^^^^^^^^^^^^^^ sqlalchemy.exc.OperationalError: (psycopg2.OperationalError) connection to server at "db.pjomptqavgnixbcoomvy.supabase.co" (2a05:d014:1c06:5f0f:d8b7:40ee:d73f:2bb2), port 5432 failed: Cannot assign requested address Is the server running on that host and accepting TCP/IP connections? (Background on this error at: https://sqlalche.me/e/20/e3q8) Python process exited with exit status: 1. The logs above can help with debugging the issue.
Apr 08 00:23:35.86
GET
500
last-x7uk3k9q6-mostafalol1233s-projects.vercel.app
/
ith_frames_removed File "/var/task/main.py", line 87, in <module> db.create_all() File "/var/task/flask_sqlalchemy/extension.py", line 900, in create_all self._call_for_binds(bind_key, "create_all") File "/var/task/flask_sqlalchemy/extension.py", line 881, in _call_for_binds getattr(metadata, op_name)(bind=engine) File "/var/task/sqlalchemy/sql/schema.py", line 5925, in create_all bind._run_ddl_visitor( File "/var/task/sqlalchemy/engine/base.py", line 3248, in _run_ddl_visitor with self.begin() as conn: ^^^^^^^^^^^^ File "/var/lang/lib/python3.12/contextlib.py", line 137, in __enter__ return next(self.gen) ^^^^^^^^^^^^^^ File "/var/task/sqlalchemy/engine/base.py", line 3238, in begin with self.connect() as conn: ^^^^^^^^^^^^^^ File "/var/task/sqlalchemy/engine/base.py", line 3274, in connect return self._connection_cls(self) ^^^^^^^^^^^^^^^^^^^^^^^^^^ File "/var/task/sqlalchemy/engine/base.py", line 148, in __init__ Connection._handle_dbapi_exception_noconnection( File "/var/task/sqlalchemy/engine/base.py", line 2439, in _handle_dbapi_exception_noconnection raise sqlalchemy_exception.with_traceback(exc_info[2]) from e File "/var/task/sqlalchemy/engine/base.py", line 146, in __init__ self._dbapi_connection = engine.raw_connection() ^^^^^^^^^^^^^^^^^^^^^^^ File "/var/task/sqlalchemy/engine/base.py", line 3298, in raw_connection return self.pool.connect() ^^^^^^^^^^^^^^^^^^^ File "/var/task/sqlalchemy/pool/base.py", line 449, in connect return _ConnectionFairy._checkout(self) ^^^^^^^^^^^^^^^^^^^^^^^^^^^^^^^^ File "/var/task/sqlalchemy/pool/base.py", line 1264, in _checkout fairy = _ConnectionRecord.checkout(pool) ^^^^^^^^^^^^^^^^^^^^^^^^^^^^^^^^ File "/var/task/sqlalchemy/pool/base.py", line 713, in checkout rec = pool._do_get() ^^^^^^^^^^^^^^ File "/var/task/sqlalchemy/pool/impl.py", line 179, in _do_get with util.safe_reraise(): ^^^^^^^^^^^^^^^^^^^ File "/var/task/sqlalchemy/util/langhelpers.py", line 146, in __exit__ raise exc_value.with_traceback(exc_tb) File "/var/task/sqlalchemy/pool/impl.py", line 177, in _do_get return self._create_connection() ^^^^^^^^^^^^^^^^^^^^^^^^^ File "/var/task/sqlalchemy/pool/base.py", line 390, in _create_connection return _ConnectionRecord(self) ^^^^^^^^^^^^^^^^^^^^^^^ File "/var/task/sqlalchemy/pool/base.py", line 675, in __init__ self.__connect() File "/var/task/sqlalchemy/pool/base.py", line 901, in __connect with util.safe_reraise(): ^^^^^^^^^^^^^^^^^^^ File "/var/task/sqlalchemy/util/langhelpers.py", line 146, in __exit__ raise exc_value.with_traceback(exc_tb) File "/var/task/sqlalchemy/pool/base.py", line 897, in __connect self.dbapi_connection = connection = pool._invoke_creator(self) ^^^^^^^^^^^^^^^^^^^^^^^^^^ File "/var/task/sqlalchemy/engine/create.py", line 646, in connect return dialect.connect(*cargs, **cparams) ^^^^^^^^^^^^^^^^^^^^^^^^^^^^^^^^^^ File "/var/task/sqlalchemy/engine/default.py", line 625, in connect return self.loaded_dbapi.connect(*cargs, **cparams) # type: ignore[no-any-return] # NOQA: E501 ^^^^^^^^^^^^^^^^^^^^^^^^^^^^^^^^^^^^^^^^^^^^ File "/var/task/psycopg2/__init__.py", line 122, in connect conn = _connect(dsn, connection_factory=connection_factory, **kwasync) ^^^^^^^^^^^^^^^^^^^^^^^^^^^^^^^^^^^^^^^^^^^^^^^^^^^^^^^^^^^^^^^ sqlalchemy.exc.OperationalError: (psycopg2.OperationalError) connection to server at "db.pjomptqavgnixbcoomvy.supabase.co" (2a05:d014:1c06:5f0f:d8b7:40ee:d73f:2bb2), port 5432 failed: Cannot assign requested address Is the server running on that host and accepting TCP/IP connections? (Background on this error at: https://sqlalche.me/e/20/e3q8) Python process exited with exit status: 1. The logs above can help with debugging the issue.
Apr 08 00:23:35.85
GET
500
last-x7uk3k9q6-mostafalol1233s-projects.vercel.app
/
ith_frames_removed File "/var/task/main.py", line 87, in <module> db.create_all() File "/var/task/flask_sqlalchemy/extension.py", line 900, in create_all self._call_for_binds(bind_key, "create_all") File "/var/task/flask_sqlalchemy/extension.py", line 881, in _call_for_binds getattr(metadata, op_name)(bind=engine) File "/var/task/sqlalchemy/sql/schema.py", line 5925, in create_all bind._run_ddl_visitor( File "/var/task/sqlalchemy/engine/base.py", line 3248, in _run_ddl_visitor with self.begin() as conn: ^^^^^^^^^^^^ File "/var/lang/lib/python3.12/contextlib.py", line 137, in __enter__ return next(self.gen) ^^^^^^^^^^^^^^ File "/var/task/sqlalchemy/engine/base.py", line 3238, in begin with self.connect() as conn: ^^^^^^^^^^^^^^ File "/var/task/sqlalchemy/engine/base.py", line 3274, in connect return self._connection_cls(self) ^^^^^^^^^^^^^^^^^^^^^^^^^^ File "/var/task/sqlalchemy/engine/base.py", line 148, in __init__ Connection._handle_dbapi_exception_noconnection( File "/var/task/sqlalchemy/engine/base.py", line 2439, in _handle_dbapi_exception_noconnection raise sqlalchemy_exception.with_traceback(exc_info[2]) from e File "/var/task/sqlalchemy/engine/base.py", line 146, in __init__ self._dbapi_connection = engine.raw_connection() ^^^^^^^^^^^^^^^^^^^^^^^ File "/var/task/sqlalchemy/engine/base.py", line 3298, in raw_connection return self.pool.connect() ^^^^^^^^^^^^^^^^^^^ File "/var/task/sqlalchemy/pool/base.py", line 449, in connect return _ConnectionFairy._checkout(self) ^^^^^^^^^^^^^^^^^^^^^^^^^^^^^^^^ File "/var/task/sqlalchemy/pool/base.py", line 1264, in _checkout fairy = _ConnectionRecord.checkout(pool) ^^^^^^^^^^^^^^^^^^^^^^^^^^^^^^^^ File "/var/task/sqlalchemy/pool/base.py", line 713, in checkout rec = pool._do_get() ^^^^^^^^^^^^^^ File "/var/task/sqlalchemy/pool/impl.py", line 179, in _do_get with util.safe_reraise(): ^^^^^^^^^^^^^^^^^^^ File "/var/task/sqlalchemy/util/langhelpers.py", line 146, in __exit__ raise exc_value.with_traceback(exc_tb) File "/var/task/sqlalchemy/pool/impl.py", line 177, in _do_get return self._create_connection() ^^^^^^^^^^^^^^^^^^^^^^^^^ File "/var/task/sqlalchemy/pool/base.py", line 390, in _create_connection return _ConnectionRecord(self) ^^^^^^^^^^^^^^^^^^^^^^^ File "/var/task/sqlalchemy/pool/base.py", line 675, in __init__ self.__connect() File "/var/task/sqlalchemy/pool/base.py", line 901, in __connect with util.safe_reraise(): ^^^^^^^^^^^^^^^^^^^ File "/var/task/sqlalchemy/util/langhelpers.py", line 146, in __exit__ raise exc_value.with_traceback(exc_tb) File "/var/task/sqlalchemy/pool/base.py", line 897, in __connect self.dbapi_connection = connection = pool._invoke_creator(self) ^^^^^^^^^^^^^^^^^^^^^^^^^^ File "/var/task/sqlalchemy/engine/create.py", line 646, in connect return dialect.connect(*cargs, **cparams) ^^^^^^^^^^^^^^^^^^^^^^^^^^^^^^^^^^ File "/var/task/sqlalchemy/engine/default.py", line 625, in connect return self.loaded_dbapi.connect(*cargs, **cparams) # type: ignore[no-any-return] # NOQA: E501 ^^^^^^^^^^^^^^^^^^^^^^^^^^^^^^^^^^^^^^^^^^^^ File "/var/task/psycopg2/__init__.py", line 122, in connect conn = _connect(dsn, connection_factory=connection_factory, **kwasync) ^^^^^^^^^^^^^^^^^^^^^^^^^^^^^^^^^^^^^^^^^^^^^^^^^^^^^^^^^^^^^^^ sqlalchemy.exc.OperationalError: (psycopg2.OperationalError) connection to server at "db.pjomptqavgnixbcoomvy.supabase.co" (2a05:d014:1c06:5f0f:d8b7:40ee:d73f:2bb2), port 5432 failed: Cannot assign requested address Is the server running on that host and accepting TCP/IP connections? (Background on this error at: https://sqlalche.me/e/20/e3q8) Python process exited with exit status: 1. The logs above can help with debugging the issue.
Apr 08 00:23:35.58
GET
500
last-x7uk3k9q6-mostafalol1233s-projects.vercel.app
/
ith_frames_removed File "/var/task/main.py", line 87, in <module> db.create_all() File "/var/task/flask_sqlalchemy/extension.py", line 900, in create_all self._call_for_binds(bind_key, "create_all") File "/var/task/flask_sqlalchemy/extension.py", line 881, in _call_for_binds getattr(metadata, op_name)(bind=engine) File "/var/task/sqlalchemy/sql/schema.py", line 5925, in create_all bind._run_ddl_visitor( File "/var/task/sqlalchemy/engine/base.py", line 3248, in _run_ddl_visitor with self.begin() as conn: ^^^^^^^^^^^^ File "/var/lang/lib/python3.12/contextlib.py", line 137, in __enter__ return next(self.gen) ^^^^^^^^^^^^^^ File "/var/task/sqlalchemy/engine/base.py", line 3238, in begin with self.connect() as conn: ^^^^^^^^^^^^^^ File "/var/task/sqlalchemy/engine/base.py", line 3274, in connect return self._connection_cls(self) ^^^^^^^^^^^^^^^^^^^^^^^^^^ File "/var/task/sqlalchemy/engine/base.py", line 148, in __init__ Connection._handle_dbapi_exception_noconnection( File "/var/task/sqlalchemy/engine/base.py", line 2439, in _handle_dbapi_exception_noconnection raise sqlalchemy_exception.with_traceback(exc_info[2]) from e File "/var/task/sqlalchemy/engine/base.py", line 146, in __init__ self._dbapi_connection = engine.raw_connection() ^^^^^^^^^^^^^^^^^^^^^^^ File "/var/task/sqlalchemy/engine/base.py", line 3298, in raw_connection return self.pool.connect() ^^^^^^^^^^^^^^^^^^^ File "/var/task/sqlalchemy/pool/base.py", line 449, in connect return _ConnectionFairy._checkout(self) ^^^^^^^^^^^^^^^^^^^^^^^^^^^^^^^^ File "/var/task/sqlalchemy/pool/base.py", line 1264, in _checkout fairy = _ConnectionRecord.checkout(pool) ^^^^^^^^^^^^^^^^^^^^^^^^^^^^^^^^ File "/var/task/sqlalchemy/pool/base.py", line 713, in checkout rec = pool._do_get() ^^^^^^^^^^^^^^ File "/var/task/sqlalchemy/pool/impl.py", line 179, in _do_get with util.safe_reraise(): ^^^^^^^^^^^^^^^^^^^ File "/var/task/sqlalchemy/util/langhelpers.py", line 146, in __exit__ raise exc_value.with_traceback(exc_tb) File "/var/task/sqlalchemy/pool/impl.py", line 177, in _do_get return self._create_connection() ^^^^^^^^^^^^^^^^^^^^^^^^^ File "/var/task/sqlalchemy/pool/base.py", line 390, in _create_connection return _ConnectionRecord(self) ^^^^^^^^^^^^^^^^^^^^^^^ File "/var/task/sqlalchemy/pool/base.py", line 675, in __init__ self.__connect() File "/var/task/sqlalchemy/pool/base.py", line 901, in __connect with util.safe_reraise(): ^^^^^^^^^^^^^^^^^^^ File "/var/task/sqlalchemy/util/langhelpers.py", line 146, in __exit__ raise exc_value.with_traceback(exc_tb) File "/var/task/sqlalchemy/pool/base.py", line 897, in __connect self.dbapi_connection = connection = pool._invoke_creator(self) ^^^^^^^^^^^^^^^^^^^^^^^^^^ File "/var/task/sqlalchemy/engine/create.py", line 646, in connect return dialect.connect(*cargs, **cparams) ^^^^^^^^^^^^^^^^^^^^^^^^^^^^^^^^^^ File "/var/task/sqlalchemy/engine/default.py", line 625, in connect return self.loaded_dbapi.connect(*cargs, **cparams) # type: ignore[no-any-return] # NOQA: E501 ^^^^^^^^^^^^^^^^^^^^^^^^^^^^^^^^^^^^^^^^^^^^ File "/var/task/psycopg2/__init__.py", line 122, in connect conn = _connect(dsn, connection_factory=connection_factory, **kwasync) ^^^^^^^^^^^^^^^^^^^^^^^^^^^^^^^^^^^^^^^^^^^^^^^^^^^^^^^^^^^^^^^ sqlalchemy.exc.OperationalError: (psycopg2.OperationalError) connection to server at "db.pjomptqavgnixbcoomvy.supabase.co" (2a05:d014:1c06:5f0f:d8b7:40ee:d73f:2bb2), port 5432 failed: Cannot assign requested address Is the server running on that host and accepting TCP/IP connections? (Background on this error at: https://sqlalche.me/e/20/e3q8) Python process exited with exit status: 1. The logs above can help with debugging the issue.
Apr 08 00:23:35.50
GET
500
last-x7uk3k9q6-mostafalol1233s-projects.vercel.app
/
ith_frames_removed File "/var/task/main.py", line 87, in <module> db.create_all() File "/var/task/flask_sqlalchemy/extension.py", line 900, in create_all self._call_for_binds(bind_key, "create_all") File "/var/task/flask_sqlalchemy/extension.py", line 881, in _call_for_binds getattr(metadata, op_name)(bind=engine) File "/var/task/sqlalchemy/sql/schema.py", line 5925, in create_all bind._run_ddl_visitor( File "/var/task/sqlalchemy/engine/base.py", line 3248, in _run_ddl_visitor with self.begin() as conn: ^^^^^^^^^^^^ File "/var/lang/lib/python3.12/contextlib.py", line 137, in __enter__ return next(self.gen) ^^^^^^^^^^^^^^ File "/var/task/sqlalchemy/engine/base.py", line 3238, in begin with self.connect() as conn: ^^^^^^^^^^^^^^ File "/var/task/sqlalchemy/engine/base.py", line 3274, in connect return self._connection_cls(self) ^^^^^^^^^^^^^^^^^^^^^^^^^^ File "/var/task/sqlalchemy/engine/base.py", line 148, in __init__ Connection._handle_dbapi_exception_noconnection( File "/var/task/sqlalchemy/engine/base.py", line 2439, in _handle_dbapi_exception_noconnection raise sqlalchemy_exception.with_traceback(exc_info[2]) from e File "/var/task/sqlalchemy/engine/base.py", line 146, in __init__ self._dbapi_connection = engine.raw_connection() ^^^^^^^^^^^^^^^^^^^^^^^ File "/var/task/sqlalchemy/engine/base.py", line 3298, in raw_connection return self.pool.connect() ^^^^^^^^^^^^^^^^^^^ File "/var/task/sqlalchemy/pool/base.py", line 449, in connect return _ConnectionFairy._checkout(self) ^^^^^^^^^^^^^^^^^^^^^^^^^^^^^^^^ File "/var/task/sqlalchemy/pool/base.py", line 1264, in _checkout fairy = _ConnectionRecord.checkout(pool) ^^^^^^^^^^^^^^^^^^^^^^^^^^^^^^^^ File "/var/task/sqlalchemy/pool/base.py", line 713, in checkout rec = pool._do_get() ^^^^^^^^^^^^^^ File "/var/task/sqlalchemy/pool/impl.py", line 179, in _do_get with util.safe_reraise(): ^^^^^^^^^^^^^^^^^^^ File "/var/task/sqlalchemy/util/langhelpers.py", line 146, in __exit__ raise exc_value.with_traceback(exc_tb) File "/var/task/sqlalchemy/pool/impl.py", line 177, in _do_get return self._create_connection() ^^^^^^^^^^^^^^^^^^^^^^^^^ File "/var/task/sqlalchemy/pool/base.py", line 390, in _create_connection return _ConnectionRecord(self) ^^^^^^^^^^^^^^^^^^^^^^^ File "/var/task/sqlalchemy/pool/base.py", line 675, in __init__ self.__connect() File "/var/task/sqlalchemy/pool/base.py", line 901, in __connect with util.safe_reraise(): ^^^^^^^^^^^^^^^^^^^ File "/var/task/sqlalchemy/util/langhelpers.py", line 146, in __exit__ raise exc_value.with_traceback(exc_tb) File "/var/task/sqlalchemy/pool/base.py", line 897, in __connect self.dbapi_connection = connection = pool._invoke_creator(self) ^^^^^^^^^^^^^^^^^^^^^^^^^^ File "/var/task/sqlalchemy/engine/create.py", line 646, in connect return dialect.connect(*cargs, **cparams) ^^^^^^^^^^^^^^^^^^^^^^^^^^^^^^^^^^ File "/var/task/sqlalchemy/engine/default.py", line 625, in connect return self.loaded_dbapi.connect(*cargs, **cparams) # type: ignore[no-any-return] # NOQA: E501 ^^^^^^^^^^^^^^^^^^^^^^^^^^^^^^^^^^^^^^^^^^^^ File "/var/task/psycopg2/__init__.py", line 122, in connect conn = _connect(dsn, connection_factory=connection_factory, **kwasync) ^^^^^^^^^^^^^^^^^^^^^^^^^^^^^^^^^^^^^^^^^^^^^^^^^^^^^^^^^^^^^^^ sqlalchemy.exc.OperationalError: (psycopg2.OperationalError) connection to server at "db.pjomptqavgnixbcoomvy.supabase.co" (2a05:d014:1c06:5f0f:d8b7:40ee:d73f:2bb2), port 5432 failed: Cannot assign requested address Is the server running on that host and accepting TCP/IP connections? (Background on this error at: https://sqlalche.me/e/20/e3q8) Python process exited with exit status: 1. The logs above can help with debugging the issue.
Apr 08 00:23:34.30
GET
500
last-x7uk3k9q6-mostafalol1233s-projects.vercel.app
/
ith_frames_removed File "/var/task/main.py", line 87, in <module> db.create_all() File "/var/task/flask_sqlalchemy/extension.py", line 900, in create_all self._call_for_binds(bind_key, "create_all") File "/var/task/flask_sqlalchemy/extension.py", line 881, in _call_for_binds getattr(metadata, op_name)(bind=engine) File "/var/task/sqlalchemy/sql/schema.py", line 5925, in create_all bind._run_ddl_visitor( File "/var/task/sqlalchemy/engine/base.py", line 3248, in _run_ddl_visitor with self.begin() as conn: ^^^^^^^^^^^^ File "/var/lang/lib/python3.12/contextlib.py", line 137, in __enter__ return next(self.gen) ^^^^^^^^^^^^^^ File "/var/task/sqlalchemy/engine/base.py", line 3238, in begin with self.connect() as conn: ^^^^^^^^^^^^^^ File "/var/task/sqlalchemy/engine/base.py", line 3274, in connect return self._connection_cls(self) ^^^^^^^^^^^^^^^^^^^^^^^^^^ File "/var/task/sqlalchemy/engine/base.py", line 148, in __init__ Connection._handle_dbapi_exception_noconnection( File "/var/task/sqlalchemy/engine/base.py", line 2439, in _handle_dbapi_exception_noconnection raise sqlalchemy_exception.with_traceback(exc_info[2]) from e File "/var/task/sqlalchemy/engine/base.py", line 146, in __init__ self._dbapi_connection = engine.raw_connection() ^^^^^^^^^^^^^^^^^^^^^^^ File "/var/task/sqlalchemy/engine/base.py", line 3298, in raw_connection return self.pool.connect() ^^^^^^^^^^^^^^^^^^^ File "/var/task/sqlalchemy/pool/base.py", line 449, in connect return _ConnectionFairy._checkout(self) ^^^^^^^^^^^^^^^^^^^^^^^^^^^^^^^^ File "/var/task/sqlalchemy/pool/base.py", line 1264, in _checkout fairy = _ConnectionRecord.checkout(pool) ^^^^^^^^^^^^^^^^^^^^^^^^^^^^^^^^ File "/var/task/sqlalchemy/pool/base.py", line 713, in checkout rec = pool._do_get() ^^^^^^^^^^^^^^ File "/var/task/sqlalchemy/pool/impl.py", line 179, in _do_get with util.safe_reraise(): ^^^^^^^^^^^^^^^^^^^ File "/var/task/sqlalchemy/util/langhelpers.py", line 146, in __exit__ raise exc_value.with_traceback(exc_tb) File "/var/task/sqlalchemy/pool/impl.py", line 177, in _do_get return self._create_connection() ^^^^^^^^^^^^^^^^^^^^^^^^^ File "/var/task/sqlalchemy/pool/base.py", line 390, in _create_connection return _ConnectionRecord(self) ^^^^^^^^^^^^^^^^^^^^^^^ File "/var/task/sqlalchemy/pool/base.py", line 675, in __init__ self.__connect() File "/var/task/sqlalchemy/pool/base.py", line 901, in __connect with util.safe_reraise(): ^^^^^^^^^^^^^^^^^^^ File "/var/task/sqlalchemy/util/langhelpers.py", line 146, in __exit__ raise exc_value.with_traceback(exc_tb) File "/var/task/sqlalchemy/pool/base.py", line 897, in __connect self.dbapi_connection = connection = pool._invoke_creator(self) ^^^^^^^^^^^^^^^^^^^^^^^^^^ File "/var/task/sqlalchemy/engine/create.py", line 646, in connect return dialect.connect(*cargs, **cparams) ^^^^^^^^^^^^^^^^^^^^^^^^^^^^^^^^^^ File "/var/task/sqlalchemy/engine/default.py", line 625, in connect return self.loaded_dbapi.connect(*cargs, **cparams) # type: ignore[no-any-return] # NOQA: E501 ^^^^^^^^^^^^^^^^^^^^^^^^^^^^^^^^^^^^^^^^^^^^ File "/var/task/psycopg2/__init__.py", line 122, in connect conn = _connect(dsn, connection_factory=connection_factory, **kwasync) ^^^^^^^^^^^^^^^^^^^^^^^^^^^^^^^^^^^^^^^^^^^^^^^^^^^^^^^^^^^^^^^ sqlalchemy.exc.OperationalError: (psycopg2.OperationalError) connection to server at "db.pjomptqavgnixbcoomvy.supabase.co" (2a05:d014:1c06:5f0f:d8b7:40ee:d73f:2bb2), port 5432 failed: Cannot assign requested address Is the server running on that host and accepting TCP/IP connections? (Background on this error at: https://sqlalche.me/e/20/e3q8) Python process exited with exit status: 1. The logs above can help with debugging the issue.
Apr 08 00:23:34.15
GET
500
last-x7uk3k9q6-mostafalol1233s-projects.vercel.app
/
ith_frames_removed File "/var/task/main.py", line 87, in <module> db.create_all() File "/var/task/flask_sqlalchemy/extension.py", line 900, in create_all self._call_for_binds(bind_key, "create_all") File "/var/task/flask_sqlalchemy/extension.py", line 881, in _call_for_binds getattr(metadata, op_name)(bind=engine) File "/var/task/sqlalchemy/sql/schema.py", line 5925, in create_all bind._run_ddl_visitor( File "/var/task/sqlalchemy/engine/base.py", line 3248, in _run_ddl_visitor with self.begin() as conn: ^^^^^^^^^^^^ File "/var/lang/lib/python3.12/contextlib.py", line 137, in __enter__ return next(self.gen) ^^^^^^^^^^^^^^ File "/var/task/sqlalchemy/engine/base.py", line 3238, in begin with self.connect() as conn: ^^^^^^^^^^^^^^ File "/var/task/sqlalchemy/engine/base.py", line 3274, in connect return self._connection_cls(self) ^^^^^^^^^^^^^^^^^^^^^^^^^^ File "/var/task/sqlalchemy/engine/base.py", line 148, in __init__ Connection._handle_dbapi_exception_noconnection( File "/var/task/sqlalchemy/engine/base.py", line 2439, in _handle_dbapi_exception_noconnection raise sqlalchemy_exception.with_traceback(exc_info[2]) from e File "/var/task/sqlalchemy/engine/base.py", line 146, in __init__ self._dbapi_connection = engine.raw_connection() ^^^^^^^^^^^^^^^^^^^^^^^ File "/var/task/sqlalchemy/engine/base.py", line 3298, in raw_connection return self.pool.connect() ^^^^^^^^^^^^^^^^^^^ File "/var/task/sqlalchemy/pool/base.py", line 449, in connect return _ConnectionFairy._checkout(self) ^^^^^^^^^^^^^^^^^^^^^^^^^^^^^^^^ File "/var/task/sqlalchemy/pool/base.py", line 1264, in _checkout fairy = _ConnectionRecord.checkout(pool) ^^^^^^^^^^^^^^^^^^^^^^^^^^^^^^^^ File "/var/task/sqlalchemy/pool/base.py", line 713, in checkout rec = pool._do_get() ^^^^^^^^^^^^^^ File "/var/task/sqlalchemy/pool/impl.py", line 179, in _do_get with util.safe_reraise(): ^^^^^^^^^^^^^^^^^^^ File "/var/task/sqlalchemy/util/langhelpers.py", line 146, in __exit__ raise exc_value.with_traceback(exc_tb) File "/var/task/sqlalchemy/pool/impl.py", line 177, in _do_get return self._create_connection() ^^^^^^^^^^^^^^^^^^^^^^^^^ File "/var/task/sqlalchemy/pool/base.py", line 390, in _create_connection return _ConnectionRecord(self) ^^^^^^^^^^^^^^^^^^^^^^^ File "/var/task/sqlalchemy/pool/base.py", line 675, in __init__ self.__connect() File "/var/task/sqlalchemy/pool/base.py", line 901, in __connect with util.safe_reraise(): ^^^^^^^^^^^^^^^^^^^ File "/var/task/sqlalchemy/util/langhelpers.py", line 146, in __exit__ raise exc_value.with_traceback(exc_tb) File "/var/task/sqlalchemy/pool/base.py", line 897, in __connect self.dbapi_connection = connection = pool._invoke_creator(self) ^^^^^^^^^^^^^^^^^^^^^^^^^^ File "/var/task/sqlalchemy/engine/create.py", line 646, in connect return dialect.connect(*cargs, **cparams) ^^^^^^^^^^^^^^^^^^^^^^^^^^^^^^^^^^ File "/var/task/sqlalchemy/engine/default.py", line 625, in connect return self.loaded_dbapi.connect(*cargs, **cparams) # type: ignore[no-any-return] # NOQA: E501 ^^^^^^^^^^^^^^^^^^^^^^^^^^^^^^^^^^^^^^^^^^^^ File "/var/task/psycopg2/__init__.py", line 122, in connect conn = _connect(dsn, connection_factory=connection_factory, **kwasync) ^^^^^^^^^^^^^^^^^^^^^^^^^^^^^^^^^^^^^^^^^^^^^^^^^^^^^^^^^^^^^^^ sqlalchemy.exc.OperationalError: (psycopg2.OperationalError) connection to server at "db.pjomptqavgnixbcoomvy.supabase.co" (2a05:d014:1c06:5f0f:d8b7:40ee:d73f:2bb2), port 5432 failed: Cannot assign requested address Is the server running on that host and accepting TCP/IP connections? (Background on this error at: https://sqlalche.me/e/20/e3q8) Python process exited with exit status: 1. The logs above can help with debugging the issue.
No m